Workbook

Sheet GDP
B1: 上海 | C1: 江苏 | D1: 浙江 | E1: 安徽 | F1: 内蒙古 | G1: 甘肃 | H1: 宁夏 | I1: 新疆 | K1: 单位：亿元
A2: 40908 | B2: 19195.69 | C2: 49110.27 | D2: 32318.85 | E2: 15300.65 | F2: 14359.88 | G2: 5020.37 | H2: 2102.21 | I2: 6610.05
A3: 41274 | B3: 20181.72 | C3: 54058.22 | D3: 34665.33 | E3: 17212.051 | F3: 15880.579 | G3: 5650.204 | H3: 2341.29 | I3: 7505.31
A4: 41639 | B4: 21818.15 | C4: 59753.37 | D4: 37756.58 | E4: 19229.337 | F4: 16916.503 | G4: 6330.6923 | H4: 2577.57 | I4: 8443.84
A5: 42004 | B5: 23567.695 | C5: 65088.32 | D5: 40173.03 | E5: 20848.748 | F5: 17770.189 | G5: 6836.8208 | H5: 2752.1 | I5: 9273.46
A6: 42369 | B6: 25123.45 | C6: 70116.38 | D6: 42886.49 | E6: 22005.63 | F6: 17831.509 | G6: 6790.3169 | H6: 2911.77 | I6: 9324.8
A7: 42735 | B7: 28178.65 | C7: 77388.28 | D7: 47251.36 | E7: 24407.62 | F7: 18128.1 | G7: 7200.37 | H7: 3168.59 | I7: 9649.7
A8: 43100 | B8: 30632.99 | C8: 85869.76 | D8: 51768.26 | E8: 27018 | F8: 16096.21 | G8: 7459.8995 | H8: 3443.56 | I8: 10881.96
A9: 43465 | B9: 36011.82 | C9: 93207.55 | D9: 58003 | E9: 34010.9 | F9: 16140.8 | G9: 8104.07 | H9: 3510.21 | I9: 12809.39
A10: 43830 | B10: 38155.32 | C10: 99631.52 | D10: 62351.74 | E10: 37113.98 | F10: 17212.53 | G10: 8718.3 | H10: 3748.48 | I10: 13597.11
A11: 44196 | B11: 38700.58 | C11: 102718.98 | D11: 64613.34 | E11: 38680.63 | F11: 17359.82 | G11: 9016.7 | H11: 3920.55 | I11: 13797.58
B13: =AVERAGE(B2:I11) -> 26716.47
B14: 标准化处理：
B15: =B2/$B$13 -> 0.71849648 | C15: =C2/$B$13 -> 1.838202 | D15: =D2/$B$13 -> 1.2096976 | E15: =E2/$B$13 -> 0.57270477 | F15: =F2/$B$13 -> 0.53749166 | G15: =G2/$B$13 -> 0.18791292 | H15: =H2/$B$13 -> 0.078685918 | I15: =I2/$B$13 -> 0.24741479 | K15: 19195.69
B16: =B3/$B$13 -> 0.75540368 | C16: =C3/$B$13 -> 2.0234043 | D16: =D3/$B$13 -> 1.2975266 | E16: =E3/$B$13 -> 0.64424867 | F16: =F3/$B$13 -> 0.59441156 | G16: =G3/$B$13 -> 0.21148767 | H16: =H3/$B$13 -> 0.087634705 | I16: =I3/$B$13 -> 0.28092446 | K16: 20181.72
B17: =B4/$B$13 -> 0.81665541 | C17: =C4/$B$13 -> 2.2365743 | D17: =D4/$B$13 -> 1.4132323 | E17: =E4/$B$13 -> 0.7197559 | F17: =F4/$B$13 -> 0.6331863 | G17: =G4/$B$13 -> 0.23695841 | H17: =H4/$B$13 -> 0.096478687 | I17: =I4/$B$13 -> 0.31605373 | K17: 21818.15
B18: =B5/$B$13 -> 0.88214105 | C18: =C5/$B$13 -> 2.4362619 | D18: =D5/$B$13 -> 1.5036803 | E18: =E5/$B$13 -> 0.78037058 | F18: =F5/$B$13 -> 0.66513984 | G18: =G5/$B$13 -> 0.25590284 | H18: =H5/$B$13 -> 0.10301136 | I18: =I5/$B$13 -> 0.34710648 | K18: 23567.695
B19: =B6/$B$13 -> 0.9403731 | C19: =C6/$B$13 -> 2.6244627 | D19: =D6/$B$13 -> 1.6052454 | E19: =E6/$B$13 -> 0.8236728 | F19: =F6/$B$13 -> 0.66743505 | G19: =G6/$B$13 -> 0.2541622 | H19: =H6/$B$13 -> 0.10898782 | I19: =I6/$B$13 -> 0.34902814 | K19: 25123.45
B20: =B7/$B$13 -> 1.0547295 | C20: =C7/$B$13 -> 2.8966506 | D20: =D7/$B$13 -> 1.7686228 | E20: =E7/$B$13 -> 0.91357951 | F20: =F7/$B$13 -> 0.67853649 | G20: =G7/$B$13 -> 0.26951053 | H20: =H7/$B$13 -> 0.11860062 | I20: =I7/$B$13 -> 0.36118918 | K20: 28178.65
B21: =B8/$B$13 -> 1.1465957 | C21: =C8/$B$13 -> 3.2141132 | D21: =D8/$B$13 -> 1.9376908 | E21: =E8/$B$13 -> 1.0112863 | F21: =F8/$B$13 -> 0.60248265 | G21: =G8/$B$13 -> 0.27922474 | H21: =H8/$B$13 -> 0.12889277 | I21: =I8/$B$13 -> 0.40731279 | K21: 30632.99
B22: =B9/$B$13 -> 1.3479258 | C22: =C9/$B$13 -> 3.4887674 | D22: =D9/$B$13 -> 2.1710577 | E22: =E9/$B$13 -> 1.2730312 | F22: =F9/$B$13 -> 0.60415166 | G22: =G9/$B$13 -> 0.3033361 | H22: =H9/$B$13 -> 0.13138749 | I22: =I9/$B$13 -> 0.47945667 | K22: 36011.82
B23: =B10/$B$13 -> 1.4281572 | C23: =C10/$B$13 -> 3.7292172 | D23: =D10/$B$13 -> 2.3338315 | E23: =E10/$B$13 -> 1.3891798 | F23: =F10/$B$13 -> 0.64426662 | G23: =G10/$B$13 -> 0.32632679 | H23: =H10/$B$13 -> 0.14030596 | I23: =I10/$B$13 -> 0.50894111 | K23: 38155.32
B24: =B11/$B$13 -> 1.4485663 | C24: =C11/$B$13 -> 3.8447811 | D24: =D11/$B$13 -> 2.4184834 | E24: =E11/$B$13 -> 1.4478196 | F24: =F11/$B$13 -> 0.64977969 | G24: =G11/$B$13 -> 0.33749593 | H24: =H11/$B$13 -> 0.14674656 | I24: =I11/$B$13 -> 0.51644472 | K24: 38700.58
K25: 49110.27
K26: 54058.22
K27: 59753.37
K28: 65088.32
K29: 70116.38
K30: 77388.28
K31: 85869.76
K32: 93207.55
K33: 99631.52
K34: 102718.98
K35: 32318.85
K36: 34665.33
... K94: 13797.58

Sheet 资本存量
B1: 上海 | C1: 江苏 | D1: 浙江 | E1: 安徽 | F1: 内蒙古 | G1: 甘肃 | H1: 宁夏 | I1: 新疆
A2: 2011 | B2: 28026.256 | C2: 86020.797 | D2: 48084.569 | E2: 39588.918 | F2: 33951.853 | G2: 12063.617 | H2: 5189.6943 | I2: 14155.506 | K2: 单位：亿元
A3: 2012 | B3: 30590.115 | C3: 109469.38 | D3: 60564.41 | E3: 50843.333 | F3: 42568.215 | G3: 15085.75 | H3: 6801.0018 | I3: 18955.357
A4: 2013 | B4: 33301.254 | C4: 134942.84 | D4: 74944.297 | E4: 64213.494 | F4: 52699.044 | G4: 18678.048 | H4: 8829.2486 | I4: 24867.947
A5: 2014 | B5: 36120.764 | C5: 163541.08 | D5: 91304.404 | E5: 79305.292 | F5: 65231.762 | G5: 23292.155 | H5: 11182.626 | I5: 31928.366
A6: 2015 | B6: 39005.87 | C6: 193746.3 | D6: 109203.9 | E6: 95657.536 | F6: 72671.735 | G6: 28815.728 | H6: 13642.02 | I6: 39676.274
A7: 2016 | B7: 42017.187 | C7: 224517.51 | D7: 128291.33 | E7: 113232.52 | F7: 80775.262 | G7: 34676.019 | H7: 16167.85 | I7: 46154.881
A8: 2017 | B8: 45230.137 | C8: 255964.04 | D8: 147101.35 | E8: 131548.16 | F8: 87033.997 | G8: 40881.221 | H8: 18429.115 | I8: 53813.13
A9: 2018 | B9: 48511.467 | C9: 287306.71 | D9: 166315.56 | E9: 151549.43 | F9: 88866.302 | G9: 46118.894 | H9: 19779.264 | I9: 58236.158
A10: 2019 | B10: 51866.584 | C10: 318492.17 | D10: 187052.13 | E10: 172632.54 | F10: 91113.584 | G10: 51454.795 | H10: 20653.551 | I10: 63004.579
A11: 2020 | B11: 55724.868 | C11: 346860.12 | D11: 207779.94 | E11: 193508.89 | F11: 92961.893 | G11: 57044.87 | H11: 21577.016 | I11: 69449.204
B13: =AVERAGE(B2:I11) -> 80530.687
B14: 标准化处理：
B15: =B2/$B$13 -> 0.34801958 | C15: =C2/$B$13 -> 1.0681741 | D15: =D2/$B$13 -> 0.59709622 | E15: =E2/$B$13 -> 0.4916004 | F15: =F2/$B$13 -> 0.42160144 | G15: =G2/$B$13 -> 0.14980149 | H15: =H2/$B$13 -> 0.064443686 | I15: =I2/$B$13 -> 0.17577778 | K15: 28026.256
B16: =B3/$B$13 -> 0.37985663 | C16: =C3/$B$13 -> 1.3593499 | D16: =D3/$B$13 -> 0.75206623 | E16: =E3/$B$13 -> 0.63135352 | F16: =F3/$B$13 -> 0.5285962 | G16: =G3/$B$13 -> 0.18732921 | H16: =H3/$B$13 -> 0.084452301 | I16: =I3/$B$13 -> 0.23538055 | K16: 30590.115
B17: =B4/$B$13 -> 0.41352254 | C17: =C4/$B$13 -> 1.6756698 | D17: =D4/$B$13 -> 0.93063029 | E17: =E4/$B$13 -> 0.79737919 | F17: =F4/$B$13 -> 0.65439705 | G17: =G4/$B$13 -> 0.23193703 | H17: =H4/$B$13 -> 0.10963831 | I17: =I4/$B$13 -> 0.30880088 | K17: 33301.254
B18: =B5/$B$13 -> 0.44853415 | C18: =C5/$B$13 -> 2.030792 | D18: =D5/$B$13 -> 1.133784 | E18: =E5/$B$13 -> 0.98478351 | F18: =F5/$B$13 -> 0.81002366 | G18: =G5/$B$13 -> 0.28923329 | H18: =H5/$B$13 -> 0.13886167 | I18: =I5/$B$13 -> 0.39647453 | K18: 36120.764
B19: =B6/$B$13 -> 0.48436033 | C19: =C6/$B$13 -> 2.4058692 | D19: =D6/$B$13 -> 1.3560533 | E19: =E6/$B$13 -> 1.1878396 | F19: =F6/$B$13 -> 0.90241046 | G19: =G6/$B$13 -> 0.35782296 | H19: =H6/$B$13 -> 0.16940151 | I19: =I6/$B$13 -> 0.49268515 | K19: 39005.87
B20: =B7/$B$13 -> 0.52175374 | C20: =C7/$B$13 -> 2.7879746 | D20: =D7/$B$13 -> 1.5930738 | E20: =E7/$B$13 -> 1.4060792 | F20: =F7/$B$13 -> 1.003037 | G20: =G7/$B$13 -> 0.43059385 | H20: =H7/$B$13 -> 0.20076632 | I20: =I7/$B$13 -> 0.57313408 | K20: 42017.187
B21: =B8/$B$13 -> 0.56165095 | C21: =C8/$B$13 -> 3.1784658 | D21: =D8/$B$13 -> 1.8266496 | E21: =E8/$B$13 -> 1.6335159 | F21: =F8/$B$13 -> 1.0807557 | G21: =G8/$B$13 -> 0.50764773 | H21: =H8/$B$13 -> 0.22884587 | I21: =I8/$B$13 -> 0.66823136 | K21: 45230.137
B22: =B9/$B$13 -> 0.60239728 | C22: =C9/$B$13 -> 3.5676675 | D22: =D9/$B$13 -> 2.0652445 | E22: =E9/$B$13 -> 1.8818843 | F22: =F9/$B$13 -> 1.1035085 | G22: =G9/$B$13 -> 0.5726872 | H22: =H9/$B$13 -> 0.24561151 | I22: =I9/$B$13 -> 0.72315486 | K22: 48511.467
B23: =B10/$B$13 -> 0.64405987 | C23: =C10/$B$13 -> 3.9549168 | D23: =D10/$B$13 -> 2.3227435 | E23: =E10/$B$13 -> 2.1436864 | F23: =F10/$B$13 -> 1.1314145 | G23: =G10/$B$13 -> 0.63894643 | H23: =H10/$B$13 -> 0.25646809 | I23: =I10/$B$13 -> 0.78236733 | K23: 51866.584
B24: =B11/$B$13 -> 0.6919706 | C24: =C11/$B$13 -> 4.3071794 | D24: =D11/$B$13 -> 2.5801337 | E24: =E11/$B$13 -> 2.4029211 | F24: =F11/$B$13 -> 1.1543661 | G24: =G11/$B$13 -> 0.70836189 | H24: =H11/$B$13 -> 0.26793532 | I24: =I11/$B$13 -> 0.86239428 | K24: 55724.868
K25: 86020.797
K26: 109469.38
K27: 134942.84
K28: 163541.08
K29: 193746.3
K30: 224517.51
K31: 255964.04
K32: 287306.71
K33: 318492.17
K34: 346860.12
K35: 48084.569
K36: 60564.41
... K94: 69449.204

Sheet 就业人口
B1: 上海 | C1: 江苏 | D1: 浙江 | E1: 安徽 | F1: 内蒙古 | G1: 甘肃 | H1: 宁夏 | I1: 新疆 | K1: 单位：万人
A2: 40908 | B2: 1104.33 | C2: 4758.23 | D2: 3385 | E2: 4120.9 | F2: 1388 | G2: 1379 | H2: 478.5 | I2: 1246.12
A3: 41274 | B3: 1115.5 | C3: 4759.53 | D3: 3407 | E3: 4206.8 | F3: 1379 | G3: 1358 | H3: 487.9 | I3: 1257.85
A4: 41639 | B4: 1137.35 | C4: 4759.89 | D4: 3436 | E4: 4275.9 | F4: 1370 | G4: 1352 | H4: 494 | I4: 1271.9
A5: 42004 | B5: 1365.63 | C5: 4760.83 | D5: 3459 | E5: 4311 | F5: 1360 | G5: 1348 | H5: 499.15 | I5: 1276.21
A6: 42369 | B6: 1361.51 | C6: 4758.5 | D6: 3505 | E6: 4342.1 | F6: 1351 | G6: 1346 | H6: 503.1 | I6: 1305.42
A7: 42735 | B7: 1365.24 | C7: 4756.22 | D7: 3552 | E7: 4361.6 | F7: 1326 | G7: 1341 | H7: 509.4 | I7: 1332.66
A8: 43100 | B8: 1372.65 | C8: 4757.8 | D8: 3613 | E8: 4377.9 | F8: 1317 | G8: 1337 | H8: 514.4 | I8: 1349.79
A9: 43465 | B9: 1375.66 | C9: 4750.9 | D9: 3691 | E9: 4385.3 | F9: 1304 | G9: 1337 | H9: 518.36 | I9: 1343.95
A10: 43830 | B10: 1376.2 | C10: 4745.2 | D10: 3771 | E10: 4384 | F10: 1272 | G10: 1333 | H10: 523.3 | I10: 1355.06
A11: 44196 | B11: 1374 | C11: 4893 | D11: 3857 | E11: 3243 | F11: 1242 | G11: 1331 | H11: 559.1 | I11: 1369.07
B13: =AVERAGE(B2:I11) -> 2291.2364
B14: 标准化处理：
B15: =B2/$B$13 -> 0.48197995 | C15: =C2/$B$13 -> 2.0767085 | D15: =D2/$B$13 -> 1.4773683 | E15: =E2/$B$13 -> 1.7985486 | F15: =F2/$B$13 -> 0.60578647 | G15: =G2/$B$13 -> 0.60185846 | H15: =H2/$B$13 -> 0.20883921 | I15: =I2/$B$13 -> 0.54386357 | K15: 1104.33
B16: =B3/$B$13 -> 0.48685505 | C16: =C3/$B$13 -> 2.0772759 | D16: =D3/$B$13 -> 1.4869701 | E16: =E3/$B$13 -> 1.8360393 | F16: =F3/$B$13 -> 0.60185846 | G16: =G3/$B$13 -> 0.5926931 | H16: =H3/$B$13 -> 0.2129418 | I16: =I3/$B$13 -> 0.54898308 | K16: 1115.5
B17: =B4/$B$13 -> 0.49639139 | C17: =C4/$B$13 -> 2.077433 | D17: =D4/$B$13 -> 1.499627 | E17: =E4/$B$13 -> 1.8661977 | F17: =F4/$B$13 -> 0.59793045 | G17: =G4/$B$13 -> 0.59007443 | H17: =H4/$B$13 -> 0.21560412 | I17: =I4/$B$13 -> 0.55511514 | K17: 1137.35
B18: =B5/$B$13 -> 0.59602318 | C18: =C5/$B$13 -> 2.0778432 | D18: =D5/$B$13 -> 1.5096653 | E18: =E5/$B$13 -> 1.8815169 | F18: =F5/$B$13 -> 0.593566 | G18: =G5/$B$13 -> 0.58832865 | H18: =H5/$B$13 -> 0.21785181 | I18: =I5/$B$13 -> 0.55699622 | K18: 1365.63
B19: =B6/$B$13 -> 0.59422503 | C19: =C6/$B$13 -> 2.0768263 | D19: =D6/$B$13 -> 1.5297418 | E19: =E6/$B$13 -> 1.8950904 | F19: =F6/$B$13 -> 0.58963799 | G19: =G6/$B$13 -> 0.58745576 | H19: =H6/$B$13 -> 0.21957577 | I19: =I6/$B$13 -> 0.5697448 | K19: 1361.51
B20: =B7/$B$13 -> 0.59585297 | C20: =C7/$B$13 -> 2.0758312 | D20: =D7/$B$13 -> 1.5502547 | E20: =E7/$B$13 -> 1.9036011 | F20: =F7/$B$13 -> 0.57872685 | G20: =G7/$B$13 -> 0.58527353 | H20: =H7/$B$13 -> 0.22232538 | I20: =I7/$B$13 -> 0.58163357 | K20: 1365.24
B21: =B8/$B$13 -> 0.59908703 | C21: =C8/$B$13 -> 2.0765208 | D21: =D8/$B$13 -> 1.5768779 | E21: =E8/$B$13 -> 1.9107151 | F21: =F8/$B$13 -> 0.57479884 | G21: =G8/$B$13 -> 0.58352775 | H21: =H8/$B$13 -> 0.22450761 | I21: =I8/$B$13 -> 0.58910989 | K21: 1372.65
B22: =B9/$B$13 -> 0.60040073 | C22: =C9/$B$13 -> 2.0735093 | D22: =D9/$B$13 -> 1.6109207 | E22: =E9/$B$13 -> 1.9139448 | F22: =F9/$B$13 -> 0.56912504 | G22: =G9/$B$13 -> 0.58352775 | H22: =H9/$B$13 -> 0.22623593 | I22: =I9/$B$13 -> 0.58656104 | K22: 1375.66
B23: =B10/$B$13 -> 0.60063641 | C23: =C10/$B$13 -> 2.0710216 | D23: =D10/$B$13 -> 1.6458363 | E23: =E10/$B$13 -> 1.9133774 | F23: =F10/$B$13 -> 0.55515878 | G23: =G10/$B$13 -> 0.58178196 | H23: =H10/$B$13 -> 0.22839197 | I23: =I10/$B$13 -> 0.59140995 | K23: 1376.2
B24: =B11/$B$13 -> 0.59967623 | C24: =C11/$B$13 -> 2.1355282 | D24: =D11/$B$13 -> 1.6833706 | E24: =E11/$B$13 -> 1.415393 | F24: =F11/$B$13 -> 0.54206542 | G24: =G11/$B$13 -> 0.58090907 | H24: =H11/$B$13 -> 0.24401673 | I24: =I11/$B$13 -> 0.59752456 | K24: 1374
K25: 4758.23
K26: 4759.53
K27: 4759.89
K28: 4760.83
K29: 4758.5
K30: 4756.22
K31: 4757.8
K32: 4750.9
K33: 4745.2
K34: 4893
K35: 3385
K36: 3407
... K94: 1369.07

Sheet 能源消耗量
B1: 上海 | C1: 江苏 | D1: 浙江 | E1: 安徽 | F1: 内蒙古 | G1: 甘肃 | H1: 宁夏 | I1: 新疆 | L1: 单位：万吨标准煤
A2: 40908 | B2: 10489.09 | C2: 27588.97 | D2: 17827.27 | E2: 10570.23 | F2: 16140.03 | G2: 6393.69 | H2: 4719.9 | I2: 9474.5
A3: 41274 | B3: 10573 | C3: 28849.84 | D3: 18076.18 | E3: 11357.95 | F3: 16912.92 | G3: 6893.76 | H3: 4895.2 | I3: 11293.7
A4: 41639 | B4: 10890.39 | C4: 29205.38 | D4: 18640 | E4: 12060.36 | F4: 17544.17 | G4: 7286.72 | H4: 5186.8 | I4: 13631.8
A5: 42004 | B5: 10639.86 | C5: 29863.03 | D5: 18826 | E5: 12011.02 | F5: 18167.46 | G5: 7521.45 | H5: 5336.2 | I5: 14926.1
A6: 42369 | B6: 10930.53 | C6: 30374.14 | D6: 19610 | E6: 12301.23 | F6: 18783.71 | G6: 7488.5 | H6: 5711.9 | I6: 15666.1
A7: 42735 | B7: 11241.73 | C7: 31209.71 | D7: 20275.6 | E7: 12662.89 | F7: 19309.66 | G7: 7299.93 | H7: 5787.5 | I7: 16302.2
A8: 43100 | B8: 11381.85 | C8: 31602.09 | D8: 21030.01 | E8: 13018.71 | F8: 19763.44 | G8: 7503.63 | H8: 6798.2 | I8: 17386.3
A9: 43465 | B9: 11453.73 | C9: 31635.2 | D9: 21674.56 | E9: 13294.71 | F9: 23068.47 | G9: 7822.54 | H9: 7530.2 | I9: 17694
A10: 43830 | B10: 11696.46 | C10: 32525.97 | D10: 22393 | E10: 13869.73 | F10: 25345.57 | G10: 7818.02 | H10: 8166.7 | I10: 18489.8
A11: 44196 | B11: 11099.59 | C11: 32672.49 | D11: 24660 | E11: 14697.9 | F11: 27133.65 | G11: 8104.71 | H11: 8581.8 | I11: 18981.8
B13: =AVERAGE(B2:I11) -> 15470.539
B14: 标准化处理：
B15: =B2/$B$13 -> 0.67800417 | C15: =C2/$B$13 -> 1.7833231 | D15: =D2/$B$13 -> 1.1523367 | E15: =E2/$B$13 -> 0.68324898 | F15: =F2/$B$13 -> 1.0432752 | G15: =G2/$B$13 -> 0.41328165 | H15: =H2/$B$13 -> 0.30508956 | I15: =I2/$B$13 -> 0.6124221 | L15: 10489.09
B16: =B3/$B$13 -> 0.68342803 | C16: =C3/$B$13 -> 1.8648245 | D16: =D3/$B$13 -> 1.168426 | E16: =E3/$B$13 -> 0.7341664 | F16: =F3/$B$13 -> 1.093234 | G16: =G3/$B$13 -> 0.44560567 | H16: =H3/$B$13 -> 0.31642078 | I16: =I3/$B$13 -> 0.73001334 | L16: 10573
B17: =B4/$B$13 -> 0.70394379 | C17: =C4/$B$13 -> 1.8878062 | D17: =D4/$B$13 -> 1.2048707 | E17: =E4/$B$13 -> 0.77956947 | F17: =F4/$B$13 -> 1.1340374 | G17: =G4/$B$13 -> 0.47100621 | H17: =H4/$B$13 -> 0.33526951 | I17: =I4/$B$13 -> 0.88114576 | L17: 10890.39
B18: =B5/$B$13 -> 0.68774979 | C18: =C5/$B$13 -> 1.9303161 | D18: =D5/$B$13 -> 1.2168936 | E18: =E5/$B$13 -> 0.77638018 | F18: =F5/$B$13 -> 1.1743262 | G18: =G5/$B$13 -> 0.48617892 | H18: =H5/$B$13 -> 0.34492657 | I18: =I5/$B$13 -> 0.96480801 | L18: 10639.86
B19: =B6/$B$13 -> 0.7065384 | C19: =C6/$B$13 -> 1.9633537 | D19: =D6/$B$13 -> 1.2675706 | E19: =E6/$B$13 -> 0.79513906 | F19: =F6/$B$13 -> 1.21416 | G19: =G6/$B$13 -> 0.48404907 | H19: =H6/$B$13 -> 0.36921144 | I19: =I6/$B$13 -> 1.0126409 | L19: 10930.53
B20: =B7/$B$13 -> 0.72665406 | C20: =C7/$B$13 -> 2.0173641 | D20: =D7/$B$13 -> 1.3105943 | E20: =E7/$B$13 -> 0.8185164 | F20: =F7/$B$13 -> 1.2481569 | G20: =G7/$B$13 -> 0.47186009 | H20: =H7/$B$13 -> 0.37409815 | I20: =I7/$B$13 -> 1.0537577 | L20: 11241.73
B21: =B8/$B$13 -> 0.73571127 | C21: =C8/$B$13 -> 2.0427271 | D21: =D8/$B$13 -> 1.3593586 | E21: =E8/$B$13 -> 0.84151625 | F21: =F8/$B$13 -> 1.2774888 | G21: =G8/$B$13 -> 0.48502705 | H21: =H8/$B$13 -> 0.43942877 | I21: =I8/$B$13 -> 1.1238328 | L21: 11381.85
B22: =B9/$B$13 -> 0.74035752 | C22: =C9/$B$13 -> 2.0448673 | D22: =D9/$B$13 -> 1.4010216 | E22: =E9/$B$13 -> 0.85935661 | F22: =F9/$B$13 -> 1.4911226 | G22: =G9/$B$13 -> 0.50564107 | H22: =H9/$B$13 -> 0.48674451 | I22: =I9/$B$13 -> 1.1437223 | L22: 11453.73
B23: =B10/$B$13 -> 0.75604734 | C23: =C10/$B$13 -> 2.1024458 | D23: =D10/$B$13 -> 1.4474609 | E23: =E10/$B$13 -> 0.89652532 | F23: =F10/$B$13 -> 1.638312 | G23: =G10/$B$13 -> 0.5053489 | H23: =H10/$B$13 -> 0.52788723 | I23: =I10/$B$13 -> 1.195162 | L23: 11696.46
B24: =B11/$B$13 -> 0.71746627 | C24: =C11/$B$13 -> 2.1119167 | D24: =D11/$B$13 -> 1.5939975 | E24: =E11/$B$13 -> 0.95005739 | F24: =F11/$B$13 -> 1.7538917 | G24: =G11/$B$13 -> 0.52388026 | H24: =H11/$B$13 -> 0.55471887 | I24: =I11/$B$13 -> 1.2269644 | L24: 11099.59
L25: 27588.97
L26: 28849.84
L27: 29205.38
L28: 29863.03
L29: 30374.14
L30: 31209.71
L31: 31602.09
L32: 31635.2
L33: 32525.97
L34: 32672.49
L35: 17827.27
L36: 18076.18
... L94: 18981.8

Sheet CO2排放量
B1: 上海 | C1: 江苏 | D1: 浙江 | E1: 安徽 | F1: 内蒙古 | G1: 甘肃 | H1: 宁夏 | I1: 新疆 | K1: 单位：百万吨
A2: 40908 | B2: 170.60296 | C2: 613.10789 | D2: 398.62266 | E2: 315.38719 | F2: 740.51601 | G2: 169.69415 | H2: 190.94823 | I2: 286.3111
A3: 41274 | B3: 168.52072 | C3: 619.98859 | D3: 383.59346 | E3: 355.907 | F3: 788.69167 | G3: 173.75378 | H3: 188.56962 | I3: 333.4408
A4: 41639 | B4: 181.78292 | C4: 638.44095 | D4: 387.56092 | E4: 387.18004 | F4: 783.74309 | G4: 181.46649 | H4: 187.75607 | I4: 336.33677
A5: 42004 | B5: 156.54657 | C5: 621.07117 | D5: 380.7947 | E5: 401.79524 | F5: 806.00009 | G5: 180.46855 | H5: 195.21583 | I5: 366.25967
A6: 42369 | B6: 161.64688 | C6: 634.16124 | D6: 381.50132 | E6: 392.8483 | F6: 753.79994 | G6: 176.5753 | H6: 193.37849 | I6: 379.0918
A7: 42735 | B7: 158.22523 | C7: 653.11684 | D7: 379.17654 | E7: 380.17731 | F7: 754.61517 | G7: 169.71653 | H7: 189.71723 | I7: 410.85326
A8: 43100 | B8: 156.57805 | C8: 645.04872 | D8: 401.44068 | E8: 397.01638 | F8: 765.07294 | G8: 173.98677 | H8: 226.23798 | I8: 452.26484
A9: 43465 | B9: 151.47448 | C9: 644.96547 | D9: 401.65883 | E9: 392.4285 | F9: 857.57321 | G9: 182.49649 | H9: 235.93473 | I9: 480.94605
A10: 43830 | B10: 159.4973 | C10: 636.58205 | D10: 419.14663 | E10: 398.96247 | F10: 972.78728 | G10: 185.44138 | H10: 251.89874 | I10: 519.30517
A11: 44196 | B11: 154.62688 | C11: 628.06253 | D11: 454.55451 | E11: 397.17087 | F11: 1046.6622 | G11: 195.98653 | H11: 259.51291 | I11: 555.46735
B13: =AVERAGE(B2:I11) -> 400.74331
B14: 标准化处理：
B15: =B2/$B$13 -> 0.42571631 | C15: =C2/$B$13 -> 1.5299267 | D15: =D2/$B$13 -> 0.9947082 | E15: =E2/$B$13 -> 0.7870055 | F15: =F2/$B$13 -> 1.8478562 | G15: =G2/$B$13 -> 0.4234485 | H15: =H2/$B$13 -> 0.47648512 | I15: =I2/$B$13 -> 0.71445009 | K15: 170.60296
B16: =B3/$B$13 -> 0.42052036 | C16: =C3/$B$13 -> 1.5470965 | D16: =D3/$B$13 -> 0.95720488 | E16: =E3/$B$13 -> 0.88811712 | F16: =F3/$B$13 -> 1.9680719 | G16: =G3/$B$13 -> 0.43357873 | H16: =H3/$B$13 -> 0.47054963 | I16: =I3/$B$13 -> 0.8320558 | K16: 168.52072
B17: =B4/$B$13 -> 0.45361436 | C17: =C4/$B$13 -> 1.5931419 | D17: =D4/$B$13 -> 0.96710514 | E17: =E4/$B$13 -> 0.96615471 | F17: =F4/$B$13 -> 1.9557234 | G17: =G4/$B$13 -> 0.45282475 | H17: =H4/$B$13 -> 0.46851954 | I17: =I4/$B$13 -> 0.8392823 | K17: 181.78292
B18: =B5/$B$13 -> 0.39064051 | C18: =C5/$B$13 -> 1.549798 | D18: =D5/$B$13 -> 0.95022097 | E18: =E5/$B$13 -> 1.0026249 | F18: =F5/$B$13 -> 2.0112627 | G18: =G5/$B$13 -> 0.45033453 | H18: =H5/$B$13 -> 0.48713434 | I18: =I5/$B$13 -> 0.91395078 | K18: 156.54657
B19: =B6/$B$13 -> 0.40336763 | C19: =C6/$B$13 -> 1.5824624 | D19: =D6/$B$13 -> 0.95198424 | E19: =E6/$B$13 -> 0.98029906 | F19: =F6/$B$13 -> 1.8810044 | G19: =G6/$B$13 -> 0.44061945 | H19: =H6/$B$13 -> 0.48254951 | I19: =I6/$B$13 -> 0.94597161 | K19: 161.64688
B20: =B7/$B$13 -> 0.39482936 | C20: =C7/$B$13 -> 1.6297635 | D20: =D7/$B$13 -> 0.94618306 | E20: =E7/$B$13 -> 0.94868037 | F20: =F7/$B$13 -> 1.8830387 | G20: =G7/$B$13 -> 0.42350433 | H20: =H7/$B$13 -> 0.47341335 | I20: =I7/$B$13 -> 1.025228 | K20: 158.22523
B21: =B8/$B$13 -> 0.39071906 | C21: =C8/$B$13 -> 1.6096306 | D21: =D8/$B$13 -> 1.0017402 | E21: =E8/$B$13 -> 0.99069995 | F21: =F8/$B$13 -> 1.9091346 | G21: =G8/$B$13 -> 0.43416012 | H21: =H8/$B$13 -> 0.56454586 | I21: =I8/$B$13 -> 1.1285649 | K21: 156.57805
B22: =B9/$B$13 -> 0.3779838 | C22: =C9/$B$13 -> 1.6094229 | D22: =D9/$B$13 -> 1.0022845 | E22: =E9/$B$13 -> 0.97925153 | F22: =F9/$B$13 -> 2.1399564 | G22: =G9/$B$13 -> 0.45539496 | H22: =H9/$B$13 -> 0.58874277 | I22: =I9/$B$13 -> 1.2001349 | K22: 151.47448
B23: =B10/$B$13 -> 0.39800365 | C23: =C10/$B$13 -> 1.5885032 | D23: =D10/$B$13 -> 1.0459229 | E23: =E10/$B$13 -> 0.99555615 | F23: =F10/$B$13 -> 2.4274573 | G23: =G10/$B$13 -> 0.46274353 | H23: =H10/$B$13 -> 0.62857877 | I23: =I10/$B$13 -> 1.2958548 | K23: 159.4973
B24: =B11/$B$13 -> 0.38585018 | C24: =C11/$B$13 -> 1.5672439 | D24: =D11/$B$13 -> 1.1342785 | E24: =E11/$B$13 -> 0.99108545 | F24: =F11/$B$13 -> 2.611802 | G24: =G11/$B$13 -> 0.48905751 | H24: =H11/$B$13 -> 0.64757889 | I24: =I11/$B$13 -> 1.3860926 | K24: 154.62688
K25: 613.10789
K26: 619.98859
K27: 638.44095
K28: 621.07117
K29: 634.16124
K30: 653.11684
K31: 645.04872
K32: 644.96547
K33: 636.58205
K34: 628.06253
K35: 398.62266
K36: 383.59346
... K94: 555.46735

Sheet OLS回归结果
B1: -b1 | C1: x1 | D1: x2 | E1: x3 | F1: y1+b1 | G1: x1*x1 | H1: x2*x2 | I1: x3*x3 | J1: x1*x2 | K1: x1*x3 | L1: x2*x3 | M1: (y1+b1)^2 | N1: x1*(y1+b1) | O1: x2*(y1+b1) | P1: x3*(y1+b1) | Q1: id | R1: time | S1: y1 | U1: 𝛾1 | V1: 影子价格
A2: 上海2011 | B2: =-CO2排放量!K15*100 -> -17060.296 | C2: =就业人口!K15 -> 1104.33 | D2: =资本存量!K15 -> 28026.256 | E2: =能源消耗量!L15 -> 10489.09 | F2: =S2-B2 -> 36255.986 | G2: =C2*C2 -> 1219544.7 | H2: =D2*D2 -> 7.8547101e+08 | I2: =E2*E2 -> 1.1002101e+08 | J2: =C2*D2 -> 30950235 | K2: =C2*E2 -> 11583417 | L2: =D2*E2 -> 2.9396992e+08 | M2: =F2*F2 -> 1.3144966e+09 | N2: =C2*F2 -> 40038573 | O2: =D2*F2 -> 1.0161195e+09 | P2: =E2*F2 -> 3.802923e+08 | Q2: 1 | R2: 1 | S2: =GDP!K15 -> 19195.69 | U2: =1+U14 -> 7.571449 | V2: =-($U$2+$U$4*B2*(-1)+$U$8*C2+$U$10*D2+$U$12*E2+$U$6*S2)/($U$14+$U$16*S2+$U$18*C2+$U$20*D2+$U$22*E2+$U$6*B2*(-1)) -> -0.99987783
A3: 上海2012 | B3: =-CO2排放量!K16*100 -> -16852.072 | C3: =就业人口!K16 -> 1115.5 | D3: =资本存量!K16 -> 30590.115 | E3: =能源消耗量!L16 -> 10573 | F3: =S3-B3 -> 37033.792 | G3: =C3*C3 -> 1244340.2 | H3: =D3*D3 -> 9.3575514e+08 | I3: =E3*E3 -> 111788329 | J3: =C3*D3 -> 34123273 | K3: =C3*E3 -> 11794182 | L3: =D3*E3 -> 3.2342929e+08 | M3: =F3*F3 -> 1.3715018e+09 | N3: =C3*F3 -> 41311195 | O3: =D3*F3 -> 1.132868e+09 | P3: =E3*F3 -> 3.9155828e+08 | Q3: 1 | R3: 2 | S3: =GDP!K16 -> 20181.72 | U3: 𝛾11 | V3: =-($U$2+$U$4*B3*(-1)+$U$8*C3+$U$10*D3+$U$12*E3+$U$6*S3)/($U$14+$U$16*S3+$U$18*C3+$U$20*D3+$U$22*E3+$U$6*B3*(-1)) -> -0.99986505
A4: 上海2013 | B4: =-CO2排放量!K17*100 -> -18178.292 | C4: =就业人口!K17 -> 1137.35 | D4: =资本存量!K17 -> 33301.254 | E4: =能源消耗量!L17 -> 10890.39 | F4: =S4-B4 -> 39996.442 | G4: =C4*C4 -> 1293565 | H4: =D4*D4 -> 1.1089735e+09 | I4: =E4*E4 -> 1.1860059e+08 | J4: =C4*D4 -> 37875181 | K4: =C4*E4 -> 12386185 | L4: =D4*E4 -> 3.6266364e+08 | M4: =F4*F4 -> 1.5997154e+09 | N4: =C4*F4 -> 45489953 | O4: =D4*F4 -> 1.3319317e+09 | P4: =E4*F4 -> 4.3557685e+08 | Q4: 1 | R4: 3 | S4: =GDP!K17 -> 21818.15 | U4: -0.6547 | V4: =-($U$2+$U$4*B4*(-1)+$U$8*C4+$U$10*D4+$U$12*E4+$U$6*S4)/($U$14+$U$16*S4+$U$18*C4+$U$20*D4+$U$22*E4+$U$6*B4*(-1)) -> -0.99987471
A5: 上海2014 | B5: =-CO2排放量!K18*100 -> -15654.657 | C5: =就业人口!K18 -> 1365.63 | D5: =资本存量!K18 -> 36120.764 | E5: =能源消耗量!L18 -> 10639.86 | F5: =S5-B5 -> 39222.353 | G5: =C5*C5 -> 1864945.3 | H5: =D5*D5 -> 1.3047096e+09 | I5: =E5*E5 -> 1.1320662e+08 | J5: =C5*D5 -> 49327599 | K5: =C5*E5 -> 14530112 | L5: =D5*E5 -> 3.8431987e+08 | M5: =F5*F5 -> 1.5383929e+09 | N5: =C5*F5 -> 53563221 | O5: =D5*F5 -> 1.4167413e+09 | P5: =E5*F5 -> 4.1732034e+08 | Q5: 1 | R5: 4 | S5: =GDP!K18 -> 23567.695 | U5: μ11 | V5: =-($U$2+$U$4*B5*(-1)+$U$8*C5+$U$10*D5+$U$12*E5+$U$6*S5)/($U$14+$U$16*S5+$U$18*C5+$U$20*D5+$U$22*E5+$U$6*B5*(-1)) -> -0.99982227
A6: 上海2015 | B6: =-CO2排放量!K19*100 -> -16164.688 | C6: =就业人口!K19 -> 1361.51 | D6: =资本存量!K19 -> 39005.87 | E6: =能源消耗量!L19 -> 10930.53 | F6: =S6-B6 -> 41288.138 | G6: =C6*C6 -> 1853709.5 | H6: =D6*D6 -> 1.5214579e+09 | I6: =E6*E6 -> 1.1947649e+08 | J6: =C6*D6 -> 53106883 | K6: =C6*E6 -> 14882026 | L6: =D6*E6 -> 4.2635484e+08 | M6: =F6*F6 -> 1.7047104e+09 | N6: =C6*F6 -> 56214213 | O6: =D6*F6 -> 1.6104798e+09 | P6: =E6*F6 -> 4.5130123e+08 | Q6: 1 | R6: 5 | S6: =GDP!K19 -> 25123.45 | U6: =U4 -> -0.6547 | V6: =-($U$2+$U$4*B6*(-1)+$U$8*C6+$U$10*D6+$U$12*E6+$U$6*S6)/($U$14+$U$16*S6+$U$18*C6+$U$20*D6+$U$22*E6+$U$6*B6*(-1)) -> -0.99982061
A7: 上海2016 | B7: =-CO2排放量!K20*100 -> -15822.523 | C7: =就业人口!K20 -> 1365.24 | D7: =资本存量!K20 -> 42017.187 | E7: =能源消耗量!L20 -> 11241.73 | F7: =S7-B7 -> 44001.173 | G7: =C7*C7 -> 1863880.3 | H7: =D7*D7 -> 1.765444e+09 | I7: =E7*E7 -> 1.2637649e+08 | J7: =C7*D7 -> 57363544 | K7: =C7*E7 -> 15347659 | L7: =D7*E7 -> 4.7234587e+08 | M7: =F7*F7 -> 1.9361032e+09 | N7: =C7*F7 -> 60072161 | O7: =D7*F7 -> 1.8488055e+09 | P7: =E7*F7 -> 4.946493e+08 | Q7: 1 | R7: 6 | S7: =GDP!K20 -> 28178.65 | U7: η11 | V7: =-($U$2+$U$4*B7*(-1)+$U$8*C7+$U$10*D7+$U$12*E7+$U$6*S7)/($U$14+$U$16*S7+$U$18*C7+$U$20*D7+$U$22*E7+$U$6*B7*(-1)) -> -0.99982962
A8: 上海2017 | B8: =-CO2排放量!K21*100 -> -15657.805 | C8: =就业人口!K21 -> 1372.65 | D8: =资本存量!K21 -> 45230.137 | E8: =能源消耗量!L21 -> 11381.85 | F8: =S8-B8 -> 46290.795 | G8: =C8*C8 -> 1884168 | H8: =D8*D8 -> 2.0457653e+09 | I8: =E8*E8 -> 1.2954651e+08 | J8: =C8*D8 -> 62085147 | K8: =C8*E8 -> 15623296 | L8: =D8*E8 -> 5.1480263e+08 | M8: =F8*F8 -> 2.1428377e+09 | N8: =C8*F8 -> 63541060 | O8: =D8*F8 -> 2.093739e+09 | P8: =E8*F8 -> 5.2687488e+08 | Q8: 1 | R8: 7 | S8: =GDP!K21 -> 30632.99 | U8: 1.949462 | V8: =-($U$2+$U$4*B8*(-1)+$U$8*C8+$U$10*D8+$U$12*E8+$U$6*S8)/($U$14+$U$16*S8+$U$18*C8+$U$20*D8+$U$22*E8+$U$6*B8*(-1)) -> -0.99982678
A9: 上海2018 | B9: =-CO2排放量!K22*100 -> -15147.448 | C9: =就业人口!K22 -> 1375.66 | D9: =资本存量!K22 -> 48511.467 | E9: =能源消耗量!L22 -> 11453.73 | F9: =S9-B9 -> 51159.268 | G9: =C9*C9 -> 1892440.4 | H9: =D9*D9 -> 2.3533624e+09 | I9: =E9*E9 -> 1.3118793e+08 | J9: =C9*D9 -> 66735285 | K9: =C9*E9 -> 15756438 | L9: =D9*E9 -> 5.5563724e+08 | M9: =F9*F9 -> 2.6172707e+09 | N9: =C9*F9 -> 70377759 | O9: =D9*F9 -> 2.4818111e+09 | P9: =E9*F9 -> 5.8596444e+08 | Q9: 1 | R9: 8 | S9: =GDP!K22 -> 36011.82 | U9: η21 | V9: =-($U$2+$U$4*B9*(-1)+$U$8*C9+$U$10*D9+$U$12*E9+$U$6*S9)/($U$14+$U$16*S9+$U$18*C9+$U$20*D9+$U$22*E9+$U$6*B9*(-1)) -> -0.9998637
A10: 上海2019 | B10: =-CO2排放量!K23*100 -> -15949.73 | C10: =就业人口!K23 -> 1376.2 | D10: =资本存量!K23 -> 51866.584 | E10: =能源消耗量!L23 -> 11696.46 | F10: =S10-B10 -> 54105.05 | G10: =C10*C10 -> 1893926.4 | H10: =D10*D10 -> 2.6901425e+09 | I10: =E10*E10 -> 1.3680718e+08 | J10: =C10*D10 -> 71378793 | K10: =C10*E10 -> 16096668 | L10: =D10*E10 -> 6.0665542e+08 | M10: =F10*F10 -> 2.9273565e+09 | N10: =C10*F10 -> 74459370 | O10: =D10*F10 -> 2.8062441e+09 | P10: =E10*F10 -> 6.3283756e+08 | Q10: 1 | R10: 9 | S10: =GDP!K23 -> 38155.32 | U10: 0.4939281 | V10: =-($U$2+$U$4*B10*(-1)+$U$8*C10+$U$10*D10+$U$12*E10+$U$6*S10)/($U$14+$U$16*S10+$U$18*C10+$U$20*D10+$U$22*E10+$U$6*B10*(-1)) -> -0.99986873
A11: 上海2020 | B11: =-CO2排放量!K24*100 -> -15462.688 | C11: =就业人口!K24 -> 1374 | D11: =资本存量!K24 -> 55724.868 | E11: =能源消耗量!L24 -> 11099.59 | F11: =S11-B11 -> 54163.268 | G11: =C11*C11 -> 1887876 | H11: =D11*D11 -> 3.1052609e+09 | I11: =E11*E11 -> 1.232009e+08 | J11: =C11*D11 -> 76565969 | K11: =C11*E11 -> 15250837 | L11: =D11*E11 -> 6.1852319e+08 | M11: =F11*F11 -> 2.9336596e+09 | N11: =C11*F11 -> 74420330 | O11: =D11*F11 -> 3.018241e+09 | P11: =E11*F11 -> 6.0119007e+08 | Q11: 1 | R11: 10 | S11: =GDP!K24 -> 38700.58 | U11: η31 | V11: =-($U$2+$U$4*B11*(-1)+$U$8*C11+$U$10*D11+$U$12*E11+$U$6*S11)/($U$14+$U$16*S11+$U$18*C11+$U$20*D11+$U$22*E11+$U$6*B11*(-1)) -> -0.99982544
A12: 江苏2011 | B12: =-CO2排放量!K25*100 -> -61310.789 | C12: =就业人口!K25 -> 4758.23 | D12: =资本存量!K25 -> 86020.797 | E12: =能源消耗量!L25 -> 27588.97 | F12: =S12-B12 -> 110421.06 | G12: =C12*C12 -> 22640753 | H12: =D12*D12 -> 7.3995775e+09 | I12: =E12*E12 -> 7.6115127e+08 | J12: =C12*D12 -> 4.0930674e+08 | K12: =C12*E12 -> 1.3127466e+08 | L12: =D12*E12 -> 2.3732252e+09 | M12: =F12*F12 -> 1.219281e+10 | N12: =C12*F12 -> 5.2540879e+08 | O12: =D12*F12 -> 9.4985075e+09 | P12: =E12*F12 -> 3.0464033e+09 | Q12: 2 | R12: 1 | S12: =GDP!K25 -> 49110.27 | U12: -0.0429955 | V12: =-($U$2+$U$4*B12*(-1)+$U$8*C12+$U$10*D12+$U$12*E12+$U$6*S12)/($U$14+$U$16*S12+$U$18*C12+$U$20*D12+$U$22*E12+$U$6*B12*(-1)) -> -0.99995393
A13: 江苏2012 | B13: =-CO2排放量!K26*100 -> -61998.859 | C13: =就业人口!K26 -> 4759.53 | D13: =资本存量!K26 -> 109469.38 | E13: =能源消耗量!L26 -> 28849.84 | F13: =S13-B13 -> 116057.08 | G13: =C13*C13 -> 22653126 | H13: =D13*D13 -> 1.1983545e+10 | I13: =E13*E13 -> 8.3231327e+08 | J13: =C13*D13 -> 5.210228e+08 | K13: =C13*E13 -> 1.3731168e+08 | L13: =D13*E13 -> 3.1581741e+09 | M13: =F13*F13 -> 1.3469245e+10 | N13: =C13*F13 -> 5.5237715e+08 | O13: =D13*F13 -> 1.2704696e+10 | P13: =E13*F13 -> 3.3482281e+09 | Q13: 2 | R13: 2 | S13: =GDP!K26 -> 54058.22 | U13: β1 | V13: =-($U$2+$U$4*B13*(-1)+$U$8*C13+$U$10*D13+$U$12*E13+$U$6*S13)/($U$14+$U$16*S13+$U$18*C13+$U$20*D13+$U$22*E13+$U$6*B13*(-1)) -> -0.99992789
A14: 江苏2013 | B14: =-CO2排放量!K27*100 -> -63844.095 | C14: =就业人口!K27 -> 4759.89 | D14: =资本存量!K27 -> 134942.84 | E14: =能源消耗量!L27 -> 29205.38 | F14: =S14-B14 -> 123597.47 | G14: =C14*C14 -> 22656553 | H14: =D14*D14 -> 1.820957e+10 | I14: =E14*E14 -> 8.5295422e+08 | J14: =C14*D14 -> 6.4231307e+08 | K14: =C14*E14 -> 1.390144e+08 | L14: =D14*E14 -> 3.9410569e+09 | M14: =F14*F14 -> 1.5276333e+10 | N14: =C14*F14 -> 5.8831034e+08 | O14: =D14*F14 -> 1.6678593e+10 | P14: =E14*F14 -> 3.6097109e+09 | Q14: 2 | R14: 3 | S14: =GDP!K27 -> 59753.37 | U14: =6.571449 -> 6.571449 | V14: =-($U$2+$U$4*B14*(-1)+$U$8*C14+$U$10*D14+$U$12*E14+$U$6*S14)/($U$14+$U$16*S14+$U$18*C14+$U$20*D14+$U$22*E14+$U$6*B14*(-1)) -> -0.99983967
A15: 江苏2014 | B15: =-CO2排放量!K28*100 -> -62107.117 | C15: =就业人口!K28 -> 4760.83 | D15: =资本存量!K28 -> 163541.08 | E15: =能源消耗量!L28 -> 29863.03 | F15: =S15-B15 -> 127195.44 | G15: =C15*C15 -> 22665502 | H15: =D15*D15 -> 2.6745684e+10 | I15: =E15*E15 -> 8.9180056e+08 | J15: =C15*D15 -> 7.7859127e+08 | K15: =C15*E15 -> 1.4217281e+08 | L15: =D15*E15 -> 4.8838321e+09 | M15: =F15*F15 -> 1.6178679e+10 | N15: =C15*F15 -> 6.0555585e+08 | O15: =D15*F15 -> 2.0801679e+10 | P15: =E15*F15 -> 3.7984412e+09 | Q15: 2 | R15: 4 | S15: =GDP!K28 -> 65088.32 | U15: β11 | V15: =-($U$2+$U$4*B15*(-1)+$U$8*C15+$U$10*D15+$U$12*E15+$U$6*S15)/($U$14+$U$16*S15+$U$18*C15+$U$20*D15+$U$22*E15+$U$6*B15*(-1)) -> -1.0001816
A16: 江苏2015 | B16: =-CO2排放量!K29*100 -> -63416.124 | C16: =就业人口!K29 -> 4758.5 | D16: =资本存量!K29 -> 193746.3 | E16: =能源消耗量!L29 -> 30374.14 | F16: =S16-B16 -> 133532.5 | G16: =C16*C16 -> 22643322 | H16: =D16*D16 -> 3.753763e+10 | I16: =E16*E16 -> 9.2258838e+08 | J16: =C16*D16 -> 9.2194179e+08 | K16: =C16*E16 -> 1.4453535e+08 | L16: =D16*E16 -> 5.8848774e+09 | M16: =F16*F16 -> 1.783093e+10 | N16: =C16*F16 -> 6.3541442e+08 | O16: =D16*F16 -> 2.5871429e+10 | P16: =E16*F16 -> 4.055935e+09 | Q16: 2 | R16: 5 | S16: =GDP!K29 -> 70116.38 | U16: =U6 -> -0.6547 | V16: =-($U$2+$U$4*B16*(-1)+$U$8*C16+$U$10*D16+$U$12*E16+$U$6*S16)/($U$14+$U$16*S16+$U$18*C16+$U$20*D16+$U$22*E16+$U$6*B16*(-1)) -> -1.0000615
A17: 江苏2016 | B17: =-CO2排放量!K30*100 -> -65311.684 | C17: =就业人口!K30 -> 4756.22 | D17: =资本存量!K30 -> 224517.51 | E17: =能源消耗量!L30 -> 31209.71 | F17: =S17-B17 -> 142699.96 | G17: =C17*C17 -> 22621629 | H17: =D17*D17 -> 5.0408112e+10 | I17: =E17*E17 -> 9.74046e+08 | J17: =C17*D17 -> 1.0678547e+09 | K17: =C17*E17 -> 1.4844025e+08 | L17: =D17*E17 -> 7.0071263e+09 | M17: =F17*F17 -> 2.036328e+10 | N17: =C17*F17 -> 6.7871242e+08 | O17: =D17*F17 -> 3.2038641e+10 | P17: =E17*F17 -> 4.4536245e+09 | Q17: 2 | R17: 6 | S17: =GDP!K30 -> 77388.28 | U17: δ11 | V17: =-($U$2+$U$4*B17*(-1)+$U$8*C17+$U$10*D17+$U$12*E17+$U$6*S17)/($U$14+$U$16*S17+$U$18*C17+$U$20*D17+$U$22*E17+$U$6*B17*(-1)) -> -1.0000394
A18: 江苏2017 | B18: =-CO2排放量!K31*100 -> -64504.872 | C18: =就业人口!K31 -> 4757.8 | D18: =资本存量!K31 -> 255964.04 | E18: =能源消耗量!L31 -> 31602.09 | F18: =S18-B18 -> 150374.63 | G18: =C18*C18 -> 22636661 | H18: =D18*D18 -> 6.5517589e+10 | I18: =E18*E18 -> 9.9869209e+08 | J18: =C18*D18 -> 1.2178257e+09 | K18: =C18*E18 -> 1.5035642e+08 | L18: =D18*E18 -> 8.0889986e+09 | M18: =F18*F18 -> 2.261253e+10 | N18: =C18*F18 -> 7.1545242e+08 | O18: =D18*F18 -> 3.8490498e+10 | P18: =E18*F18 -> 4.7521527e+09 | Q18: 2 | R18: 7 | S18: =GDP!K31 -> 85869.76 | U18: =U8 -> 1.949462 | V18: =-($U$2+$U$4*B18*(-1)+$U$8*C18+$U$10*D18+$U$12*E18+$U$6*S18)/($U$14+$U$16*S18+$U$18*C18+$U$20*D18+$U$22*E18+$U$6*B18*(-1)) -> -1.0000279
A19: 江苏2018 | B19: =-CO2排放量!K32*100 -> -64496.547 | C19: =就业人口!K32 -> 4750.9 | D19: =资本存量!K32 -> 287306.71 | E19: =能源消耗量!L32 -> 31635.2 | F19: =S19-B19 -> 157704.1 | G19: =C19*C19 -> 22571051 | H19: =D19*D19 -> 8.2545147e+10 | I19: =E19*E19 -> 1.0007859e+09 | J19: =C19*D19 -> 1.3649655e+09 | K19: =C19*E19 -> 1.5029567e+08 | L19: =D19*E19 -> 9.0890053e+09 | M19: =F19*F19 -> 2.4870582e+10 | N19: =C19*F19 -> 7.4923639e+08 | O19: =D19*F19 -> 4.5309445e+10 | P19: =E19*F19 -> 4.9890006e+09 | Q19: 2 | R19: 8 | S19: =GDP!K32 -> 93207.55 | U19: δ21 | V19: =-($U$2+$U$4*B19*(-1)+$U$8*C19+$U$10*D19+$U$12*E19+$U$6*S19)/($U$14+$U$16*S19+$U$18*C19+$U$20*D19+$U$22*E19+$U$6*B19*(-1)) -> -1.0000215
A20: 江苏2019 | B20: =-CO2排放量!K33*100 -> -63658.205 | C20: =就业人口!K33 -> 4745.2 | D20: =资本存量!K33 -> 318492.17 | E20: =能源消耗量!L33 -> 32525.97 | F20: =S20-B20 -> 163289.72 | G20: =C20*C20 -> 22516923 | H20: =D20*D20 -> 1.0143726e+11 | I20: =E20*E20 -> 1.0579387e+09 | J20: =C20*D20 -> 1.511309e+09 | K20: =C20*E20 -> 1.5434223e+08 | L20: =D20*E20 -> 1.0359267e+10 | M20: =F20*F20 -> 2.6663534e+10 | N20: =C20*F20 -> 7.748424e+08 | O20: =D20*F20 -> 5.2006498e+10 | P20: =E20*F20 -> 5.3111567e+09 | Q20: 2 | R20: 9 | S20: =GDP!K33 -> 99631.52 | U20: =U10 -> 0.4939281 | V20: =-($U$2+$U$4*B20*(-1)+$U$8*C20+$U$10*D20+$U$12*E20+$U$6*S20)/($U$14+$U$16*S20+$U$18*C20+$U$20*D20+$U$22*E20+$U$6*B20*(-1)) -> -1.0000172
A21: 江苏2020 | B21: =-CO2排放量!K34*100 -> -62806.253 | C21: =就业人口!K34 -> 4893 | D21: =资本存量!K34 -> 346860.12 | E21: =能源消耗量!L34 -> 32672.49 | F21: =S21-B21 -> 165525.23 | G21: =C21*C21 -> 23941449 | H21: =D21*D21 -> 1.2031194e+11 | I21: =E21*E21 -> 1.0674916e+09 | J21: =C21*D21 -> 1.6971865e+09 | K21: =C21*E21 -> 1.5986649e+08 | L21: =D21*E21 -> 1.1332784e+10 | M21: =F21*F21 -> 2.7398603e+10 | N21: =C21*F21 -> 8.0991496e+08 | O21: =D21*F21 -> 5.7414101e+10 | P21: =E21*F21 -> 5.4081215e+09 | Q21: 2 | R21: 10 | S21: =GDP!K34 -> 102718.98 | U21: δ31 | V21: =-($U$2+$U$4*B21*(-1)+$U$8*C21+$U$10*D21+$U$12*E21+$U$6*S21)/($U$14+$U$16*S21+$U$18*C21+$U$20*D21+$U$22*E21+$U$6*B21*(-1)) -> -1.0000141
A22: 浙江2011 | B22: =-CO2排放量!K35*100 -> -39862.266 | C22: =就业人口!K35 -> 3385 | D22: =资本存量!K35 -> 48084.569 | E22: =能源消耗量!L35 -> 17827.27 | F22: =S22-B22 -> 72181.116 | G22: =C22*C22 -> 11458225 | H22: =D22*D22 -> 2.3121257e+09 | I22: =E22*E22 -> 3.1781156e+08 | J22: =C22*D22 -> 1.6276627e+08 | K22: =C22*E22 -> 60345309 | L22: =D22*E22 -> 8.5721659e+08 | M22: =F22*F22 -> 5.2101135e+09 | N22: =C22*F22 -> 2.4433308e+08 | O22: =D22*F22 -> 3.4707978e+09 | P22: =E22*F22 -> 1.2867922e+09 | Q22: 3 | R22: 1 | S22: =GDP!K35 -> 32318.85 | U22: =U12 -> -0.0429955 | V22: =-($U$2+$U$4*B22*(-1)+$U$8*C22+$U$10*D22+$U$12*E22+$U$6*S22)/($U$14+$U$16*S22+$U$18*C22+$U$20*D22+$U$22*E22+$U$6*B22*(-1)) -> -0.9999434
A23: 浙江2012 | B23: =-CO2排放量!K36*100 -> -38359.346 | C23: =就业人口!K36 -> 3407 | D23: =资本存量!K36 -> 60564.41 | E23: =能源消耗量!L36 -> 18076.18 | F23: =S23-B23 -> 73024.676 | G23: =C23*C23 -> 11607649 | H23: =D23*D23 -> 3.6680478e+09 | I23: =E23*E23 -> 3.2674828e+08 | J23: =C23*D23 -> 2.0634295e+08 | K23: =C23*E23 -> 61585545 | L23: =D23*E23 -> 1.0947732e+09 | M23: =F23*F23 -> 5.3326032e+09 | N23: =C23*F23 -> 2.4879507e+08 | O23: =D23*F23 -> 4.4226964e+09 | P23: =E23*F23 -> 1.3200072e+09 | Q23: 3 | R23: 2 | S23: =GDP!K36 -> 34665.33 | V23: =-($U$2+$U$4*B23*(-1)+$U$8*C23+$U$10*D23+$U$12*E23+$U$6*S23)/($U$14+$U$16*S23+$U$18*C23+$U$20*D23+$U$22*E23+$U$6*B23*(-1)) -> -0.99991683
A24: 浙江2013 | B24: =-CO2排放量!K37*100 -> -38756.092 | C24: =就业人口!K37 -> 3436 | D24: =资本存量!K37 -> 74944.297 | E24: =能源消耗量!L37 -> 18640 | F24: =S24-B24 -> 76512.672 | G24: =C24*C24 -> 11806096 | H24: =D24*D24 -> 5.6166476e+09 | I24: =E24*E24 -> 347449600 | J24: =C24*D24 -> 2.575086e+08 | K24: =C24*E24 -> 64047040 | L24: =D24*E24 -> 1.3969617e+09 | M24: =F24*F24 -> 5.854189e+09 | N24: =C24*F24 -> 2.6289754e+08 | O24: =D24*F24 -> 5.7341884e+09 | P24: =E24*F24 -> 1.4261962e+09 | Q24: 3 | R24: 3 | S24: =GDP!K37 -> 37756.58 | V24: =-($U$2+$U$4*B24*(-1)+$U$8*C24+$U$10*D24+$U$12*E24+$U$6*S24)/($U$14+$U$16*S24+$U$18*C24+$U$20*D24+$U$22*E24+$U$6*B24*(-1)) -> -0.99986057
A25: 浙江2014 | B25: =-CO2排放量!K38*100 -> -38079.47 | C25: =就业人口!K38 -> 3459 | D25: =资本存量!K38 -> 91304.404 | E25: =能源消耗量!L38 -> 18826 | F25: =S25-B25 -> 78252.5 | G25: =C25*C25 -> 11964681 | H25: =D25*D25 -> 8.3364942e+09 | I25: =E25*E25 -> 354418276 | J25: =C25*D25 -> 3.1582193e+08 | K25: =C25*E25 -> 65119134 | L25: =D25*E25 -> 1.7188967e+09 | M25: =F25*F25 -> 6.1234538e+09 | N25: =C25*F25 -> 2.706754e+08 | O25: =D25*F25 -> 7.1447979e+09 | P25: =E25*F25 -> 1.4731816e+09 | Q25: 3 | R25: 4 | S25: =GDP!K38 -> 40173.03 | V25: =-($U$2+$U$4*B25*(-1)+$U$8*C25+$U$10*D25+$U$12*E25+$U$6*S25)/($U$14+$U$16*S25+$U$18*C25+$U$20*D25+$U$22*E25+$U$6*B25*(-1)) -> -0.99483934
A26: 浙江2015 | B26: =-CO2排放量!K39*100 -> -38150.132 | C26: =就业人口!K39 -> 3505 | D26: =资本存量!K39 -> 109203.9 | E26: =能源消耗量!L39 -> 19610 | F26: =S26-B26 -> 81036.622 | G26: =C26*C26 -> 12285025 | H26: =D26*D26 -> 1.1925492e+10 | I26: =E26*E26 -> 384552100 | J26: =C26*D26 -> 3.8275967e+08 | K26: =C26*E26 -> 68733050 | L26: =D26*E26 -> 2.1414885e+09 | M26: =F26*F26 -> 6.5669341e+09 | N26: =C26*F26 -> 2.8403336e+08 | O26: =D26*F26 -> 8.8495153e+09 | P26: =E26*F26 -> 1.5891282e+09 | Q26: 3 | R26: 5 | S26: =GDP!K39 -> 42886.49 | V26: =-($U$2+$U$4*B26*(-1)+$U$8*C26+$U$10*D26+$U$12*E26+$U$6*S26)/($U$14+$U$16*S26+$U$18*C26+$U$20*D26+$U$22*E26+$U$6*B26*(-1)) -> -1.0001453
A27: 浙江2016 | B27: =-CO2排放量!K40*100 -> -37917.654 | C27: =就业人口!K40 -> 3552 | D27: =资本存量!K40 -> 128291.33 | E27: =能源消耗量!L40 -> 20275.6 | F27: =S27-B27 -> 85169.014 | G27: =C27*C27 -> 12616704 | H27: =D27*D27 -> 1.6458665e+10 | I27: =E27*E27 -> 4.1109996e+08 | J27: =C27*D27 -> 4.5569079e+08 | K27: =C27*E27 -> 72018931 | L27: =D27*E27 -> 2.6011836e+09 | M27: =F27*F27 -> 7.2537609e+09 | N27: =C27*F27 -> 3.0252034e+08 | O27: =D27*F27 -> 1.0926446e+10 | P27: =E27*F27 -> 1.7268529e+09 | Q27: 3 | R27: 6 | S27: =GDP!K40 -> 47251.36 | V27: =-($U$2+$U$4*B27*(-1)+$U$8*C27+$U$10*D27+$U$12*E27+$U$6*S27)/($U$14+$U$16*S27+$U$18*C27+$U$20*D27+$U$22*E27+$U$6*B27*(-1)) -> -1.0000732
A28: 浙江2017 | B28: =-CO2排放量!K41*100 -> -40144.068 | C28: =就业人口!K41 -> 3613 | D28: =资本存量!K41 -> 147101.35 | E28: =能源消耗量!L41 -> 21030.01 | F28: =S28-B28 -> 91912.328 | G28: =C28*C28 -> 13053769 | H28: =D28*D28 -> 2.1638807e+10 | I28: =E28*E28 -> 4.4226132e+08 | J28: =C28*D28 -> 5.3147718e+08 | K28: =C28*E28 -> 75981426 | L28: =D28*E28 -> 3.0935429e+09 | M28: =F28*F28 -> 8.447876e+09 | N28: =C28*F28 -> 3.3207924e+08 | O28: =D28*F28 -> 1.3520427e+10 | P28: =E28*F28 -> 1.9329172e+09 | Q28: 3 | R28: 7 | S28: =GDP!K41 -> 51768.26 | V28: =-($U$2+$U$4*B28*(-1)+$U$8*C28+$U$10*D28+$U$12*E28+$U$6*S28)/($U$14+$U$16*S28+$U$18*C28+$U$20*D28+$U$22*E28+$U$6*B28*(-1)) -> -1.0000537
A29: 浙江2018 | B29: =-CO2排放量!K42*100 -> -40165.883 | C29: =就业人口!K42 -> 3691 | D29: =资本存量!K42 -> 166315.56 | E29: =能源消耗量!L42 -> 21674.56 | F29: =S29-B29 -> 98168.883 | G29: =C29*C29 -> 13623481 | H29: =D29*D29 -> 2.7660864e+10 | I29: =E29*E29 -> 4.6978655e+08 | J29: =C29*D29 -> 6.1387071e+08 | K29: =C29*E29 -> 80000801 | L29: =D29*E29 -> 3.6048165e+09 | M29: =F29*F29 -> 9.6371295e+09 | N29: =C29*F29 -> 3.6234135e+08 | O29: =D29*F29 -> 1.6327012e+10 | P29: =E29*F29 -> 2.1277673e+09 | Q29: 3 | R29: 8 | S29: =GDP!K42 -> 58003 | V29: =-($U$2+$U$4*B29*(-1)+$U$8*C29+$U$10*D29+$U$12*E29+$U$6*S29)/($U$14+$U$16*S29+$U$18*C29+$U$20*D29+$U$22*E29+$U$6*B29*(-1)) -> -1.0000414
A30: 浙江2019 | B30: =-CO2排放量!K43*100 -> -41914.663 | C30: =就业人口!K43 -> 3771 | D30: =资本存量!K43 -> 187052.13 | E30: =能源消耗量!L43 -> 22393 | F30: =S30-B30 -> 104266.4 | G30: =C30*C30 -> 14220441 | H30: =D30*D30 -> 3.4988498e+10 | I30: =E30*E30 -> 501446449 | J30: =C30*D30 -> 7.0537357e+08 | K30: =C30*E30 -> 84444003 | L30: =D30*E30 -> 4.1886583e+09 | M30: =F30*F30 -> 1.0871483e+10 | N30: =C30*F30 -> 3.931886e+08 | O30: =D30*F30 -> 1.9503252e+10 | P30: =E30*F30 -> 2.3348376e+09 | Q30: 3 | R30: 9 | S30: =GDP!K43 -> 62351.74 | V30: =-($U$2+$U$4*B30*(-1)+$U$8*C30+$U$10*D30+$U$12*E30+$U$6*S30)/($U$14+$U$16*S30+$U$18*C30+$U$20*D30+$U$22*E30+$U$6*B30*(-1)) -> -1.0000328
A31: 浙江2020 | B31: =-CO2排放量!K44*100 -> -45455.451 | C31: =就业人口!K44 -> 3857 | D31: =资本存量!K44 -> 207779.94 | E31: =能源消耗量!L44 -> 24660 | F31: =S31-B31 -> 110068.79 | G31: =C31*C31 -> 14876449 | H31: =D31*D31 -> 4.3172504e+10 | I31: =E31*E31 -> 608115600 | J31: =C31*D31 -> 8.0140724e+08 | K31: =C31*E31 -> 95113620 | L31: =D31*E31 -> 5.1238534e+09 | M31: =F31*F31 -> 1.2115139e+10 | N31: =C31*F31 -> 4.2453533e+08 | O31: =D31*F31 -> 2.2870087e+10 | P31: =E31*F31 -> 2.7142964e+09 | Q31: 3 | R31: 10 | S31: =GDP!K44 -> 64613.34 | V31: =-($U$2+$U$4*B31*(-1)+$U$8*C31+$U$10*D31+$U$12*E31+$U$6*S31)/($U$14+$U$16*S31+$U$18*C31+$U$20*D31+$U$22*E31+$U$6*B31*(-1)) -> -1.000027
A32: 安徽2011 | B32: =-CO2排放量!K45*100 -> -31538.719 | C32: =就业人口!K45 -> 4120.9 | D32: =资本存量!K45 -> 39588.918 | E32: =能源消耗量!L45 -> 10570.23 | F32: =S32-B32 -> 46839.369 | G32: =C32*C32 -> 16981817 | H32: =D32*D32 -> 1.5672824e+09 | I32: =E32*E32 -> 1.1172976e+08 | J32: =C32*D32 -> 1.6314197e+08 | K32: =C32*E32 -> 43558861 | L32: =D32*E32 -> 4.1846397e+08 | M32: =F32*F32 -> 2.1939265e+09 | N32: =C32*F32 -> 1.9302036e+08 | O32: =D32*F32 -> 1.8543199e+09 | P32: =E32*F32 -> 4.9510291e+08 | Q32: 4 | R32: 1 | S32: =GDP!K45 -> 15300.65 | V32: =-($U$2+$U$4*B32*(-1)+$U$8*C32+$U$10*D32+$U$12*E32+$U$6*S32)/($U$14+$U$16*S32+$U$18*C32+$U$20*D32+$U$22*E32+$U$6*B32*(-1)) -> -0.99971639
A33: 安徽2012 | B33: =-CO2排放量!K46*100 -> -35590.7 | C33: =就业人口!K46 -> 4206.8 | D33: =资本存量!K46 -> 50843.333 | E33: =能源消耗量!L46 -> 11357.95 | F33: =S33-B33 -> 52802.75 | G33: =C33*C33 -> 17697166 | H33: =D33*D33 -> 2.5850445e+09 | I33: =E33*E33 -> 1.2900303e+08 | J33: =C33*D33 -> 2.1388773e+08 | K33: =C33*E33 -> 47780624 | L33: =D33*E33 -> 5.7747603e+08 | M33: =F33*F33 -> 2.7881304e+09 | N33: =C33*F33 -> 2.2213061e+08 | O33: =D33*F33 -> 2.6846678e+09 | P33: =E33*F33 -> 5.99731e+08 | Q33: 4 | R33: 2 | S33: =GDP!K46 -> 17212.051 | V33: =-($U$2+$U$4*B33*(-1)+$U$8*C33+$U$10*D33+$U$12*E33+$U$6*S33)/($U$14+$U$16*S33+$U$18*C33+$U$20*D33+$U$22*E33+$U$6*B33*(-1)) -> -0.99942455
A34: 安徽2013 | B34: =-CO2排放量!K47*100 -> -38718.004 | C34: =就业人口!K47 -> 4275.9 | D34: =资本存量!K47 -> 64213.494 | E34: =能源消耗量!L47 -> 12060.36 | F34: =S34-B34 -> 57947.341 | G34: =C34*C34 -> 18283321 | H34: =D34*D34 -> 4.1233728e+09 | I34: =E34*E34 -> 1.4545228e+08 | J34: =C34*D34 -> 2.7457048e+08 | K34: =C34*E34 -> 51568893 | L34: =D34*E34 -> 7.7443785e+08 | M34: =F34*F34 -> 3.3578943e+09 | N34: =C34*F34 -> 2.4777704e+08 | O34: =D34*F34 -> 3.7210012e+09 | P34: =E34*F34 -> 6.988658e+08 | Q34: 4 | R34: 3 | S34: =GDP!K47 -> 19229.337 | V34: =-($U$2+$U$4*B34*(-1)+$U$8*C34+$U$10*D34+$U$12*E34+$U$6*S34)/($U$14+$U$16*S34+$U$18*C34+$U$20*D34+$U$22*E34+$U$6*B34*(-1)) -> -1.000624
A35: 安徽2014 | B35: =-CO2排放量!K48*100 -> -40179.524 | C35: =就业人口!K48 -> 4311 | D35: =资本存量!K48 -> 79305.292 | E35: =能源消耗量!L48 -> 12011.02 | F35: =S35-B35 -> 61028.272 | G35: =C35*C35 -> 18584721 | H35: =D35*D35 -> 6.2893294e+09 | I35: =E35*E35 -> 1.442646e+08 | J35: =C35*D35 -> 3.4188512e+08 | K35: =C35*E35 -> 51779507 | L35: =D35*E35 -> 9.5253745e+08 | M35: =F35*F35 -> 3.72445e+09 | N35: =C35*F35 -> 2.6309288e+08 | O35: =D35*F35 -> 4.8398649e+09 | P35: =E35*F35 -> 7.3301179e+08 | Q35: 4 | R35: 4 | S35: =GDP!K48 -> 20848.748 | V35: =-($U$2+$U$4*B35*(-1)+$U$8*C35+$U$10*D35+$U$12*E35+$U$6*S35)/($U$14+$U$16*S35+$U$18*C35+$U$20*D35+$U$22*E35+$U$6*B35*(-1)) -> -1.0001406
A36: 安徽2015 | B36: =-CO2排放量!K49*100 -> -39284.83 | C36: =就业人口!K49 -> 4342.1 | D36: =资本存量!K49 -> 95657.536 | E36: =能源消耗量!L49 -> 12301.23 | F36: =S36-B36 -> 61290.46 | G36: =C36*C36 -> 18853832 | H36: =D36*D36 -> 9.1503642e+09 | I36: =E36*E36 -> 1.5132026e+08 | J36: =C36*D36 -> 4.1535459e+08 | K36: =C36*E36 -> 53413171 | L36: =D36*E36 -> 1.1767054e+09 | M36: =F36*F36 -> 3.7565204e+09 | N36: =C36*F36 -> 2.661293e+08 | O36: =D36*F36 -> 5.8628943e+09 | P36: =E36*F36 -> 7.5394804e+08 | Q36: 4 | R36: 5 | S36: =GDP!K49 -> 22005.63 | V36: =-($U$2+$U$4*B36*(-1)+$U$8*C36+$U$10*D36+$U$12*E36+$U$6*S36)/($U$14+$U$16*S36+$U$18*C36+$U$20*D36+$U$22*E36+$U$6*B36*(-1)) -> -1.0000664
A37: 安徽2016 | B37: =-CO2排放量!K50*100 -> -38017.731 | C37: =就业人口!K50 -> 4361.6 | D37: =资本存量!K50 -> 113232.52 | E37: =能源消耗量!L50 -> 12662.89 | F37: =S37-B37 -> 62425.351 | G37: =C37*C37 -> 19023555 | H37: =D37*D37 -> 1.2821604e+10 | I37: =E37*E37 -> 1.6034878e+08 | J37: =C37*D37 -> 4.9387498e+08 | K37: =C37*E37 -> 55230461 | L37: =D37*E37 -> 1.433851e+09 | M37: =F37*F37 -> 3.8969245e+09 | N37: =C37*F37 -> 2.7227441e+08 | O37: =D37*F37 -> 7.0685801e+09 | P37: =E37*F37 -> 7.9048536e+08 | Q37: 4 | R37: 6 | S37: =GDP!K50 -> 24407.62 | V37: =-($U$2+$U$4*B37*(-1)+$U$8*C37+$U$10*D37+$U$12*E37+$U$6*S37)/($U$14+$U$16*S37+$U$18*C37+$U$20*D37+$U$22*E37+$U$6*B37*(-1)) -> -1.0000434
A38: 安徽2017 | B38: =-CO2排放量!K51*100 -> -39701.638 | C38: =就业人口!K51 -> 4377.9 | D38: =资本存量!K51 -> 131548.16 | E38: =能源消耗量!L51 -> 13018.71 | F38: =S38-B38 -> 66719.638 | G38: =C38*C38 -> 19166008 | H38: =D38*D38 -> 1.7304918e+10 | I38: =E38*E38 -> 1.6948681e+08 | J38: =C38*D38 -> 5.7590468e+08 | K38: =C38*E38 -> 56994611 | L38: =D38*E38 -> 1.7125873e+09 | M38: =F38*F38 -> 4.4515101e+09 | N38: =C38*F38 -> 2.920919e+08 | O38: =D38*F38 -> 8.7768455e+09 | P38: =E38*F38 -> 8.6860362e+08 | Q38: 4 | R38: 7 | S38: =GDP!K51 -> 27018 | V38: =-($U$2+$U$4*B38*(-1)+$U$8*C38+$U$10*D38+$U$12*E38+$U$6*S38)/($U$14+$U$16*S38+$U$18*C38+$U$20*D38+$U$22*E38+$U$6*B38*(-1)) -> -1.0000342
A39: 安徽2018 | B39: =-CO2排放量!K52*100 -> -39242.85 | C39: =就业人口!K52 -> 4385.3 | D39: =资本存量!K52 -> 151549.43 | E39: =能源消耗量!L52 -> 13294.71 | F39: =S39-B39 -> 73253.75 | G39: =C39*C39 -> 19230856 | H39: =D39*D39 -> 2.2967231e+10 | I39: =E39*E39 -> 1.7674931e+08 | J39: =C39*D39 -> 6.6458973e+08 | K39: =C39*E39 -> 58301292 | L39: =D39*E39 -> 2.0148058e+09 | M39: =F39*F39 -> 5.3661119e+09 | N39: =C39*F39 -> 3.2123967e+08 | O39: =D39*F39 -> 1.1101564e+10 | P39: =E39*F39 -> 9.7388737e+08 | Q39: 4 | R39: 8 | S39: =GDP!K52 -> 34010.9 | V39: =-($U$2+$U$4*B39*(-1)+$U$8*C39+$U$10*D39+$U$12*E39+$U$6*S39)/($U$14+$U$16*S39+$U$18*C39+$U$20*D39+$U$22*E39+$U$6*B39*(-1)) -> -1.0000287
A40: 安徽2019 | B40: =-CO2排放量!K53*100 -> -39896.247 | C40: =就业人口!K53 -> 4384 | D40: =资本存量!K53 -> 172632.54 | E40: =能源消耗量!L53 -> 13869.73 | F40: =S40-B40 -> 77010.227 | G40: =C40*C40 -> 19219456 | H40: =D40*D40 -> 2.9801993e+10 | I40: =E40*E40 -> 1.9236941e+08 | J40: =C40*D40 -> 7.5682105e+08 | K40: =C40*E40 -> 60804896 | L40: =D40*E40 -> 2.3943667e+09 | M40: =F40*F40 -> 5.9305751e+09 | N40: =C40*F40 -> 3.3761284e+08 | O40: =D40*F40 -> 1.3294471e+10 | P40: =E40*F40 -> 1.0681111e+09 | Q40: 4 | R40: 9 | S40: =GDP!K53 -> 37113.98 | V40: =-($U$2+$U$4*B40*(-1)+$U$8*C40+$U$10*D40+$U$12*E40+$U$6*S40)/($U$14+$U$16*S40+$U$18*C40+$U$20*D40+$U$22*E40+$U$6*B40*(-1)) -> -1.0000234
...

Sheet 随即前沿分析结果
B1: -b1 | C1: x1 | D1: x2 | E1: x3 | F1: y1+b1 | G1: x1*x1 | H1: x2*x2 | I1: x3*x3 | J1: x1*x2 | K1: x1*x3 | L1: x2*x3 | M1: (y1+b1)^2 | N1: x1*(y1+b1) | O1: x2*(y1+b1) | P1: x3*(y1+b1) | Q1: id | R1: time | S1: y1 | U1: 𝛾1 | X1: 影子价格
A2: 上海2011 | B2: =-CO2排放量!K15 -> -170.60296 | C2: =就业人口!K15 -> 1104.33 | D2: =资本存量!K15 -> 28026.256 | E2: =能源消耗量!L15 -> 10489.09 | F2: =S2-B2 -> 19366.293 | G2: =C2*C2 -> 1219544.7 | H2: =D2*D2 -> 7.8547101e+08 | I2: =E2*E2 -> 1.1002101e+08 | J2: =C2*D2 -> 30950235 | K2: =C2*E2 -> 11583417 | L2: =D2*E2 -> 2.9396992e+08 | M2: =F2*F2 -> 3.750533e+08 | N2: =C2*F2 -> 21386778 | O2: =D2*F2 -> 5.4276468e+08 | P2: =E2*F2 -> 2.0313479e+08 | Q2: 1 | R2: 1 | S2: =GDP!K15 -> 19195.69 | U2: =1+U14 -> 0.9074809 | V2: =-($U$2+$U$4*B2*(-1)+$U$8*C2+$U$10*D2+$U$12*E2+$U$6*S2)/($U$14+$U$16*S2+$U$18*C2+$U$20*D2+$U$22*E2+$U$6*B2*(-1)) -> -1.5569766 | X2: =-Y2/Z2*V2 -> 270.69542 | Y2: 28156.607 | Z2: 161.9502
A3: 上海2012 | B3: =-CO2排放量!K16 -> -168.52072 | C3: =就业人口!K16 -> 1115.5 | D3: =资本存量!K16 -> 30590.115 | E3: =能源消耗量!L16 -> 10573 | F3: =S3-B3 -> 20350.241 | G3: =C3*C3 -> 1244340.2 | H3: =D3*D3 -> 9.3575514e+08 | I3: =E3*E3 -> 111788329 | J3: =C3*D3 -> 34123273 | K3: =C3*E3 -> 11794182 | L3: =D3*E3 -> 3.2342929e+08 | M3: =F3*F3 -> 4.141323e+08 | N3: =C3*F3 -> 22700694 | O3: =D3*F3 -> 6.2251621e+08 | P3: =E3*F3 -> 2.151631e+08 | Q3: 1 | R3: 2 | S3: =GDP!K16 -> 20181.72 | U3: 𝛾11 | V3: =-($U$2+$U$4*B3*(-1)+$U$8*C3+$U$10*D3+$U$12*E3+$U$6*S3)/($U$14+$U$16*S3+$U$18*C3+$U$20*D3+$U$22*E3+$U$6*B3*(-1)) -> -1.5548685 | X3: =-Y3/Z3*V3 -> 270.32891 | Y3: 28156.607 | Z3: 161.9502
A4: 上海2013 | B4: =-CO2排放量!K17 -> -181.78292 | C4: =就业人口!K17 -> 1137.35 | D4: =资本存量!K17 -> 33301.254 | E4: =能源消耗量!L17 -> 10890.39 | F4: =S4-B4 -> 21999.933 | G4: =C4*C4 -> 1293565 | H4: =D4*D4 -> 1.1089735e+09 | I4: =E4*E4 -> 1.1860059e+08 | J4: =C4*D4 -> 37875181 | K4: =C4*E4 -> 12386185 | L4: =D4*E4 -> 3.6266364e+08 | M4: =F4*F4 -> 4.8399705e+08 | N4: =C4*F4 -> 25021624 | O4: =D4*F4 -> 7.3262536e+08 | P4: =E4*F4 -> 2.3958785e+08 | Q4: 1 | R4: 3 | S4: =GDP!K17 -> 21818.15 | U4: =U16 -> -3.2e-05 | V4: =-($U$2+$U$4*B4*(-1)+$U$8*C4+$U$10*D4+$U$12*E4+$U$6*S4)/($U$14+$U$16*S4+$U$18*C4+$U$20*D4+$U$22*E4+$U$6*B4*(-1)) -> -1.5447137 | X4: =-Y4/Z4*V4 -> 268.56339 | Y4: 28156.607 | Z4: 161.9502
A5: 上海2014 | B5: =-CO2排放量!K18 -> -156.54657 | C5: =就业人口!K18 -> 1365.63 | D5: =资本存量!K18 -> 36120.764 | E5: =能源消耗量!L18 -> 10639.86 | F5: =S5-B5 -> 23724.242 | G5: =C5*C5 -> 1864945.3 | H5: =D5*D5 -> 1.3047096e+09 | I5: =E5*E5 -> 1.1320662e+08 | J5: =C5*D5 -> 49327599 | K5: =C5*E5 -> 14530112 | L5: =D5*E5 -> 3.8431987e+08 | M5: =F5*F5 -> 5.6283965e+08 | N5: =C5*F5 -> 32398536 | O5: =D5*F5 -> 8.5693774e+08 | P5: =E5*F5 -> 2.5242261e+08 | Q5: 1 | R5: 4 | S5: =GDP!K18 -> 23567.695 | U5: μ11 | V5: =-($U$2+$U$4*B5*(-1)+$U$8*C5+$U$10*D5+$U$12*E5+$U$6*S5)/($U$14+$U$16*S5+$U$18*C5+$U$20*D5+$U$22*E5+$U$6*B5*(-1)) -> -1.5484889 | X5: =-Y5/Z5*V5 -> 269.21976 | Y5: 28156.607 | Z5: 161.9502
A6: 上海2015 | B6: =-CO2排放量!K19 -> -161.64688 | C6: =就业人口!K19 -> 1361.51 | D6: =资本存量!K19 -> 39005.87 | E6: =能源消耗量!L19 -> 10930.53 | F6: =S6-B6 -> 25285.097 | G6: =C6*C6 -> 1853709.5 | H6: =D6*D6 -> 1.5214579e+09 | I6: =E6*E6 -> 1.1947649e+08 | J6: =C6*D6 -> 53106883 | K6: =C6*E6 -> 14882026 | L6: =D6*E6 -> 4.2635484e+08 | M6: =F6*F6 -> 6.3933612e+08 | N6: =C6*F6 -> 34425912 | O6: =D6*F6 -> 9.8626721e+08 | P6: =E6*F6 -> 2.7637951e+08 | Q6: 1 | R6: 5 | S6: =GDP!K19 -> 25123.45 | U6: =U4 -> -3.2e-05 | V6: =-($U$2+$U$4*B6*(-1)+$U$8*C6+$U$10*D6+$U$12*E6+$U$6*S6)/($U$14+$U$16*S6+$U$18*C6+$U$20*D6+$U$22*E6+$U$6*B6*(-1)) -> -1.5410821 | X6: =-Y6/Z6*V6 -> 267.932 | Y6: 28156.607 | Z6: 161.9502
A7: 上海2016 | B7: =-CO2排放量!K20 -> -158.22523 | C7: =就业人口!K20 -> 1365.24 | D7: =资本存量!K20 -> 42017.187 | E7: =能源消耗量!L20 -> 11241.73 | F7: =S7-B7 -> 28336.875 | G7: =C7*C7 -> 1863880.3 | H7: =D7*D7 -> 1.765444e+09 | I7: =E7*E7 -> 1.2637649e+08 | J7: =C7*D7 -> 57363544 | K7: =C7*E7 -> 15347659 | L7: =D7*E7 -> 4.7234587e+08 | M7: =F7*F7 -> 8.029785e+08 | N7: =C7*F7 -> 38686636 | O7: =D7*F7 -> 1.1906358e+09 | P7: =E7*F7 -> 3.185555e+08 | Q7: 1 | R7: 6 | S7: =GDP!K20 -> 28178.65 | U7: η11 | V7: =-($U$2+$U$4*B7*(-1)+$U$8*C7+$U$10*D7+$U$12*E7+$U$6*S7)/($U$14+$U$16*S7+$U$18*C7+$U$20*D7+$U$22*E7+$U$6*B7*(-1)) -> -1.5456896 | X7: =-Y7/Z7*V7 -> 268.73307 | Y7: 28156.607 | Z7: 161.9502
A8: 上海2017 | B8: =-CO2排放量!K21 -> -156.57805 | C8: =就业人口!K21 -> 1372.65 | D8: =资本存量!K21 -> 45230.137 | E8: =能源消耗量!L21 -> 11381.85 | F8: =S8-B8 -> 30789.568 | G8: =C8*C8 -> 1884168 | H8: =D8*D8 -> 2.0457653e+09 | I8: =E8*E8 -> 1.2954651e+08 | J8: =C8*D8 -> 62085147 | K8: =C8*E8 -> 15623296 | L8: =D8*E8 -> 5.1480263e+08 | M8: =F8*F8 -> 9.479975e+08 | N8: =C8*F8 -> 42263301 | O8: =D8*F8 -> 1.3926164e+09 | P8: =E8*F8 -> 3.5044225e+08 | Q8: 1 | R8: 7 | S8: =GDP!K21 -> 30632.99 | U8: =0.0002995 -> 0.0002995 | V8: =-($U$2+$U$4*B8*(-1)+$U$8*C8+$U$10*D8+$U$12*E8+$U$6*S8)/($U$14+$U$16*S8+$U$18*C8+$U$20*D8+$U$22*E8+$U$6*B8*(-1)) -> -1.5535118 | X8: =-Y8/Z8*V8 -> 270.09303 | Y8: 28156.607 | Z8: 161.9502
A9: 上海2018 | B9: =-CO2排放量!K22 -> -151.47448 | C9: =就业人口!K22 -> 1375.66 | D9: =资本存量!K22 -> 48511.467 | E9: =能源消耗量!L22 -> 11453.73 | F9: =S9-B9 -> 36163.294 | G9: =C9*C9 -> 1892440.4 | H9: =D9*D9 -> 2.3533624e+09 | I9: =E9*E9 -> 1.3118793e+08 | J9: =C9*D9 -> 66735285 | K9: =C9*E9 -> 15756438 | L9: =D9*E9 -> 5.5563724e+08 | M9: =F9*F9 -> 1.3077839e+09 | N9: =C9*F9 -> 49748398 | O9: =D9*F9 -> 1.7543345e+09 | P9: =E9*F9 -> 4.1420461e+08 | Q9: 1 | R9: 8 | S9: =GDP!K22 -> 36011.82 | U9: η21 | V9: =-($U$2+$U$4*B9*(-1)+$U$8*C9+$U$10*D9+$U$12*E9+$U$6*S9)/($U$14+$U$16*S9+$U$18*C9+$U$20*D9+$U$22*E9+$U$6*B9*(-1)) -> -1.5974872 | X9: =-Y9/Z9*V9 -> 277.73858 | Y9: 28156.607 | Z9: 161.9502
A10: 上海2019 | B10: =-CO2排放量!K23 -> -159.4973 | C10: =就业人口!K23 -> 1376.2 | D10: =资本存量!K23 -> 51866.584 | E10: =能源消耗量!L23 -> 11696.46 | F10: =S10-B10 -> 38314.817 | G10: =C10*C10 -> 1893926.4 | H10: =D10*D10 -> 2.6901425e+09 | I10: =E10*E10 -> 1.3680718e+08 | J10: =C10*D10 -> 71378793 | K10: =C10*E10 -> 16096668 | L10: =D10*E10 -> 6.0665542e+08 | M10: =F10*F10 -> 1.4680252e+09 | N10: =C10*F10 -> 52728852 | O10: =D10*F10 -> 1.9872587e+09 | P10: =E10*F10 -> 4.4814773e+08 | Q10: 1 | R10: 9 | S10: =GDP!K23 -> 38155.32 | U10: 7.5e-06 | V10: =-($U$2+$U$4*B10*(-1)+$U$8*C10+$U$10*D10+$U$12*E10+$U$6*S10)/($U$14+$U$16*S10+$U$18*C10+$U$20*D10+$U$22*E10+$U$6*B10*(-1)) -> -1.5967783 | X10: =-Y10/Z10*V10 -> 277.61532 | Y10: 28156.607 | Z10: 161.9502
A11: 上海2020 | B11: =-CO2排放量!K24 -> -154.62688 | C11: =就业人口!K24 -> 1374 | D11: =资本存量!K24 -> 55724.868 | E11: =能源消耗量!L24 -> 11099.59 | F11: =S11-B11 -> 38855.207 | G11: =C11*C11 -> 1887876 | H11: =D11*D11 -> 3.1052609e+09 | I11: =E11*E11 -> 1.232009e+08 | J11: =C11*D11 -> 76565969 | K11: =C11*E11 -> 15250837 | L11: =D11*E11 -> 6.1852319e+08 | M11: =F11*F11 -> 1.5097271e+09 | N11: =C11*F11 -> 53387054 | O11: =D11*F11 -> 2.1652013e+09 | P11: =E11*F11 -> 4.3127687e+08 | Q11: 1 | R11: 10 | S11: =GDP!K24 -> 38700.58 | U11: η31 | V11: =-($U$2+$U$4*B11*(-1)+$U$8*C11+$U$10*D11+$U$12*E11+$U$6*S11)/($U$14+$U$16*S11+$U$18*C11+$U$20*D11+$U$22*E11+$U$6*B11*(-1)) -> -1.6350267 | X11: =-Y11/Z11*V11 -> 284.26519 | Y11: 28156.607 | Z11: 161.9502
A12: 江苏2011 | B12: =-CO2排放量!K25 -> -613.10789 | C12: =就业人口!K25 -> 4758.23 | D12: =资本存量!K25 -> 86020.797 | E12: =能源消耗量!L25 -> 27588.97 | F12: =S12-B12 -> 49723.378 | G12: =C12*C12 -> 22640753 | H12: =D12*D12 -> 7.3995775e+09 | I12: =E12*E12 -> 7.6115127e+08 | J12: =C12*D12 -> 4.0930674e+08 | K12: =C12*E12 -> 1.3127466e+08 | L12: =D12*E12 -> 2.3732252e+09 | M12: =F12*F12 -> 2.4724143e+09 | N12: =C12*F12 -> 2.3659527e+08 | O12: =D12*F12 -> 4.2772446e+09 | P12: =E12*F12 -> 1.3718168e+09 | Q12: 2 | R12: 1 | S12: =GDP!K25 -> 49110.27 | U12: 0.0001875 | V12: =-($U$2+$U$4*B12*(-1)+$U$8*C12+$U$10*D12+$U$12*E12+$U$6*S12)/($U$14+$U$16*S12+$U$18*C12+$U$20*D12+$U$22*E12+$U$6*B12*(-1)) -> -1.1798719 | X12: =-Y12/Z12*V12 -> 140.98808 | Y12: 75694.265 | Z12: 633.45454
A13: 江苏2012 | B13: =-CO2排放量!K26 -> -619.98859 | C13: =就业人口!K26 -> 4759.53 | D13: =资本存量!K26 -> 109469.38 | E13: =能源消耗量!L26 -> 28849.84 | F13: =S13-B13 -> 54678.209 | G13: =C13*C13 -> 22653126 | H13: =D13*D13 -> 1.1983545e+10 | I13: =E13*E13 -> 8.3231327e+08 | J13: =C13*D13 -> 5.210228e+08 | K13: =C13*E13 -> 1.3731168e+08 | L13: =D13*E13 -> 3.1581741e+09 | M13: =F13*F13 -> 2.9897065e+09 | N13: =C13*F13 -> 2.6024257e+08 | O13: =D13*F13 -> 5.9855896e+09 | P13: =E13*F13 -> 1.5774576e+09 | Q13: 2 | R13: 2 | S13: =GDP!K26 -> 54058.22 | U13: β1 | V13: =-($U$2+$U$4*B13*(-1)+$U$8*C13+$U$10*D13+$U$12*E13+$U$6*S13)/($U$14+$U$16*S13+$U$18*C13+$U$20*D13+$U$22*E13+$U$6*B13*(-1)) -> -1.1720098 | X13: =-Y13/Z13*V13 -> 140.0486 | Y13: 75694.265 | Z13: 633.45454
A14: 江苏2013 | B14: =-CO2排放量!K27 -> -638.44095 | C14: =就业人口!K27 -> 4759.89 | D14: =资本存量!K27 -> 134942.84 | E14: =能源消耗量!L27 -> 29205.38 | F14: =S14-B14 -> 60391.811 | G14: =C14*C14 -> 22656553 | H14: =D14*D14 -> 1.820957e+10 | I14: =E14*E14 -> 8.5295422e+08 | J14: =C14*D14 -> 6.4231307e+08 | K14: =C14*E14 -> 1.390144e+08 | L14: =D14*E14 -> 3.9410569e+09 | M14: =F14*F14 -> 3.6471708e+09 | N14: =C14*F14 -> 2.8745838e+08 | O14: =D14*F14 -> 8.1494425e+09 | P14: =E14*F14 -> 1.7637658e+09 | Q14: 2 | R14: 3 | S14: =GDP!K27 -> 59753.37 | U14: -0.0925191 | V14: =-($U$2+$U$4*B14*(-1)+$U$8*C14+$U$10*D14+$U$12*E14+$U$6*S14)/($U$14+$U$16*S14+$U$18*C14+$U$20*D14+$U$22*E14+$U$6*B14*(-1)) -> -1.1698194 | X14: =-Y14/Z14*V14 -> 139.78685 | Y14: 75694.265 | Z14: 633.45454
A15: 江苏2014 | B15: =-CO2排放量!K28 -> -621.07117 | C15: =就业人口!K28 -> 4760.83 | D15: =资本存量!K28 -> 163541.08 | E15: =能源消耗量!L28 -> 29863.03 | F15: =S15-B15 -> 65709.391 | G15: =C15*C15 -> 22665502 | H15: =D15*D15 -> 2.6745684e+10 | I15: =E15*E15 -> 8.9180056e+08 | J15: =C15*D15 -> 7.7859127e+08 | K15: =C15*E15 -> 1.4217281e+08 | L15: =D15*E15 -> 4.8838321e+09 | M15: =F15*F15 -> 4.3177241e+09 | N15: =C15*F15 -> 3.1283124e+08 | O15: =D15*F15 -> 1.0746185e+10 | P15: =E15*F15 -> 1.9622815e+09 | Q15: 2 | R15: 4 | S15: =GDP!K28 -> 65088.32 | U15: β11 | V15: =-($U$2+$U$4*B15*(-1)+$U$8*C15+$U$10*D15+$U$12*E15+$U$6*S15)/($U$14+$U$16*S15+$U$18*C15+$U$20*D15+$U$22*E15+$U$6*B15*(-1)) -> -1.1651112 | X15: =-Y15/Z15*V15 -> 139.22425 | Y15: 75694.265 | Z15: 633.45454
A16: 江苏2015 | B16: =-CO2排放量!K29 -> -634.16124 | C16: =就业人口!K29 -> 4758.5 | D16: =资本存量!K29 -> 193746.3 | E16: =能源消耗量!L29 -> 30374.14 | F16: =S16-B16 -> 70750.541 | G16: =C16*C16 -> 22643322 | H16: =D16*D16 -> 3.753763e+10 | I16: =E16*E16 -> 9.2258838e+08 | J16: =C16*D16 -> 9.2194179e+08 | K16: =C16*E16 -> 1.4453535e+08 | L16: =D16*E16 -> 5.8848774e+09 | M16: =F16*F16 -> 5.0056391e+09 | N16: =C16*F16 -> 3.3666645e+08 | O16: =D16*F16 -> 1.3707656e+10 | P16: =E16*F16 -> 2.1489868e+09 | Q16: 2 | R16: 5 | S16: =GDP!K29 -> 70116.38 | U16: -3.2e-05 | V16: =-($U$2+$U$4*B16*(-1)+$U$8*C16+$U$10*D16+$U$12*E16+$U$6*S16)/($U$14+$U$16*S16+$U$18*C16+$U$20*D16+$U$22*E16+$U$6*B16*(-1)) -> -1.1608523 | X16: =-Y16/Z16*V16 -> 138.71534 | Y16: 75694.265 | Z16: 633.45454
A17: 江苏2016 | B17: =-CO2排放量!K30 -> -653.11684 | C17: =就业人口!K30 -> 4756.22 | D17: =资本存量!K30 -> 224517.51 | E17: =能源消耗量!L30 -> 31209.71 | F17: =S17-B17 -> 78041.397 | G17: =C17*C17 -> 22621629 | H17: =D17*D17 -> 5.0408112e+10 | I17: =E17*E17 -> 9.74046e+08 | J17: =C17*D17 -> 1.0678547e+09 | K17: =C17*E17 -> 1.4844025e+08 | L17: =D17*E17 -> 7.0071263e+09 | M17: =F17*F17 -> 6.0904596e+09 | N17: =C17*F17 -> 3.7118205e+08 | O17: =D17*F17 -> 1.752166e+10 | P17: =E17*F17 -> 2.4356494e+09 | Q17: 2 | R17: 6 | S17: =GDP!K30 -> 77388.28 | U17: δ11 | V17: =-($U$2+$U$4*B17*(-1)+$U$8*C17+$U$10*D17+$U$12*E17+$U$6*S17)/($U$14+$U$16*S17+$U$18*C17+$U$20*D17+$U$22*E17+$U$6*B17*(-1)) -> -1.1569773 | X17: =-Y17/Z17*V17 -> 138.2523 | Y17: 75694.265 | Z17: 633.45454
